Workbook

Sheet 使い方
A1: 予想出来高の使い方
A2: ※本ブックの工程は、工程表「260828＿工程表【食堂・外構】新地K修正」にリンクしています（同工程表の黒塗りから各工事の工事週を設定）。
A4: ① 「週間出来高」シートで、各工事の1段目（工程）の週に 1 など何か入力 → 黒く塗られ、その週が工事期間になります。
A5: 消せば工事期間から外れます。入力できるのはこの薄黄色のセルだけです（他はロック）。
A6: ② 各工事の出来高率は、黒の週数で均等割り（合計100%）。予想出来高金額＝出来高率×契約金額。
A7: 集計行（解体撤去・改修・工事費合計など）は契約金額で加重して自動集計、工程も青で自動表示。
A8: ③ 「100%チェック」列と3行目のチェック結果で、全工事が合計100%になっているか確認できます。
A9: ④ 「月別出来高」シートに月ごとの予想出来高率・金額、「出来高曲線」シートに週別・月別のSカーブが自動反映されます。
A11: ・年末年始（12/28～1/3の週）は稼働0のため、黒を入れても出来高に含めません（灰色）。
A12: ・月をまたぐ週は月曜日の属する月に計上します。
A13: ・契約金額は「金額リスト」シート（見積書 No.260007 令和8年5月28日 ①大学会館食堂リニューアル工事、税抜）と連動しています。
A14: ・本ブックは予想出来高の計画用です（実績は扱いません）。

Sheet 金額リスト
A1: 工事費 金額リスト
A2: 凡例： 青字＝入力値（見積書 No.260007 令和8年5月28日 ①大学会館食堂リニューアル工事より）／黒字＝計算式（自動集計）
A4: 項 | B4: 名称 | C4: 金額（円） | D4: 見積書記載額（円） | E4: 差額（円） | F4: 備考
B5: 工事費 合計（税抜） | C5: =C6+C7+C13+C31 | D5: =D6+D7+D13+D31 | E5: =C5-D5 | F5: a)+b)+c)+d)
A6: a) | B6: 共通仮設工事 | C6: 4540000 | D6: 4540000 | E6: =C6-D6
A7: b) | B7: 解体撤去工事 | C7: =C8+C9 | D7: 18950000 | E7: =C7-D7 | F7: 建築＋設備
A8: b)-1 | B8: 建築工事 | C8: 7960000 | D8: 7960000 | E8: =C8-D8
A9: b)-2 | B9: 設備工事 | C9: =C10+C11+C12 | D9: 10990000 | E9: =C9-D9 | F9: 電気＋空調＋衛生
B10: 電気設備工事 | C10: 5143000 | F10: 見積書 b)-2 電気小計
B11: 空気調和設備工事 | C11: 5175000 | F11: 見積書 b)-2 ダクト撤去工事
B12: 衛生設備工事 | C12: 672000 | F12: 見積書 b)-2 配管撤去工事
A13: c) | B13: 改修工事 | C13: =C14+C27 | D13: 241710000 | E13: =C13-D13 | F13: 建築＋設備
A14: c)-1 | B14: 建築工事 | C14: =SUM(C15:C26) | D14: 163688000 | E14: =C14-D14 | F14: 明細1〜12の計
A15: 1 | B15: 直接仮設工事 | C15: 4826702
A16: 2 | B16: 躯体工事 | C16: 476900
A17: 3 | B17: 防水工事 | C17: 337100
A18: 4 | B18: タイル工事 | C18: 14987300
A19: 5 | B19: 金属工事 | C19: 20138838
A20: 6 | B20: 金属製建具工事 | C20: 8285600
A21: 7 | B21: ガラス工事 | C21: 1115138
A22: 8 | B22: 木工事 | C22: 52688330
A23: 9 | B23: 左官工事 | C23: 46124228
A24: 10 | B24: 塗装工事 | C24: 1511084
A25: 11 | B25: 内装工事 | C25: 10568020
A26: 12 | B26: 雑工事 | C26: 2628760
B27: 設備工事 | C27: =C28+C29+C30 | D27: =D13-D14 | E27: =C27-D27 | F27: 電気＋空調＋衛生（c)-2〜c)-4 の計／記載額は c)−c)-1 で逆算）
A28: c)-2 | B28: 電気設備工事 | C28: 61941000 | F28: 見積書 c)-2 計
A29: c)-3 | B29: 空気調和設備工事 | C29: 14450000 | F29: 見積書 c)-3 計
A30: c)-4 | B30: 衛生設備工事 | C30: 1631000 | F30: 見積書 c)-4 計
A31: d) | B31: 諸経費 | C31: 39800000 | D31: 39800000 | E31: =C31-D31
A32: e) | B32: 消費税及び地方消費税 | C32: 30500000 | D32: 30500000 | E32: =C32-D32 | F32: 参考（出来高計算の対象外）
B33: 工事費 合計（税込） | C33: =C5+C32 | D33: 335500000 | E33: =C33-D33 | F33: 税抜合計＋e)
B35: 集計表
B36: 区分 | C36: 解体撤去工事 | D36: 改修工事 | E36: 計
B37: 建築工事 | C37: =C8 | D37: =C14 | E37: =C37+D37
B38: 電気設備工事 | C38: =C10 | D38: =C28 | E38: =C38+D38
B39: 空気調和設備工事 | C39: =C11 | D39: =C29 | E39: =C39+D39
B40: 衛生設備工事 | C40: =C12 | D40: =C30 | E40: =C40+D40
B41: 計 | C41: =SUM(C37:C40) | D41: =SUM(D37:D40) | E41: =SUM(E37:E40)
B42: 照合（本表との差） | C42: =C41-C7 | D42: =D41-C13 | E42: =E41-C7-C13
...

Sheet 週間出来高
A1: 週間 予想出来高（工程・予想出来高率・予想出来高金額） | E1: ※工程は工程表「260828＿工程表【食堂・外構】新地K修正」にリンク
A2: 凡例： 各工事の1段目（工程）の週に何か入力（例：1 や ●）すると黒く塗られ、工事ありになります。出来高率は工事ありの週数で均等割りし、各工事の合計が100%になります。集計行は契約金額で加重平均。6行目の稼働が0の週（年末年始）は工事ありにしても割合に含めません（灰色）。工程の入力欄（薄黄色）以外はロック済み。7行目の計上月は月別出来高の集計先（月をまたぐ週は月曜の月）。出来高金額＝出来高率×契約金額。
A3: チェック結果： | B3: =IF(COUNTIF(G8:G132,"OK")=COUNTA(G8:G132),"全工事 100% OK","要確認 "&(COUNTA(G8:G132)-COUNTIF(G8:G132,"OK"))&"件")
A4: 項 | B4: 名称 | C4: 区分 | D4: 契約金額（円） | E4: 工事週数 | F4: 出来高率 計 | G4: 100%チェック | H4: 11月第1週 | I4: 11月第2週 | J4: 11月第3週 | K4: 11月第4週 | L4: 11月第5週 | M4: 12月第1週 | N4: 12月第2週 | O4: 12月第3週 | P4: 12月第4週 | Q4: 1月第1週 | R4: 1月第2週 | S4: 1月第3週 | T4: 1月第4週 | U4: 2月第1週 | V4: 2月第2週 | W4: 2月第3週 | X4: 2月第4週 | Y4: 3月第1週 | Z4: 3月第2週 | AA4: 3月第3週 | AB4: 3月第4週 | AC4: 3月第5週
H5: 11/2～11/8 | I5: 11/9～11/15 | J5: 11/16～11/22 | K5: 11/23～11/29 | L5: 11/30～12/6 | M5: 12/7～12/13 | N5: 12/14～12/20 | O5: 12/21～12/27 | P5: 12/28～1/3 | Q5: 1/4～1/10 | R5: 1/11～1/17 | S5: 1/18～1/24 | T5: 1/25～1/31 | U5: 2/1～2/7 | V5: 2/8～2/14 | W5: 2/15～2/21 | X5: 2/22～2/28 | Y5: 3/1～3/7 | Z5: 3/8～3/14 | AA5: 3/15～3/21 | AB5: 3/22～3/28 | AC5: 3/29～4/4
C6: 稼働(1/0) | H6: 1 | I6: 1 | J6: 1 | K6: 1 | L6: 1 | M6: 1 | N6: 1 | O6: 1 | P6: 0 | Q6: 1 | R6: 1 | S6: 1 | T6: 1 | U6: 1 | V6: 1 | W6: 1 | X6: 1 | Y6: 1 | Z6: 1 | AA6: 1 | AB6: 1 | AC6: 1
C7: 計上月 | H7: 11 | I7: 11 | J7: 11 | K7: 11 | L7: 11 | M7: 12 | N7: 12 | O7: 12 | P7: 12 | Q7: 1 | R7: 1 | S7: 1 | T7: 1 | U7: 2 | V7: 2 | W7: 2 | X7: 2 | Y7: 3 | Z7: 3 | AA7: 3 | AB7: 3 | AC7: 3
B8: 工事費 合計（税抜） | C8: 工程 | D8: =D13+D18+D43+D128 | E8: =COUNTIF(H9:AC9,">0") | F8: =SUM(H9:AC9) | G8: =IF(AND(ABS(F8-1)<0.0001,ABS(AC10-1)<0.0001),"OK",IF(E8=0,"工程未設定","NG")) | H8: =IF(H9>0,"■","") | I8: =IF(I9>0,"■","") | J8: =IF(J9>0,"■","") | K8: =IF(K9>0,"■","") | L8: =IF(L9>0,"■","") | M8: =IF(M9>0,"■","") | N8: =IF(N9>0,"■","") | O8: =IF(O9>0,"■","") | ... AC8: =IF(AC9>0,"■","")
C9: 今週出来高率 | H9: =IF($D8=0,0,(H14*$D13+H19*$D18+H44*$D43+H129*$D128)/$D8) | I9: =IF($D8=0,0,(I14*$D13+I19*$D18+I44*$D43+I129*$D128)/$D8) | J9: =IF($D8=0,0,(J14*$D13+J19*$D18+J44*$D43+J129*$D128)/$D8) | K9: =IF($D8=0,0,(K14*$D13+K19*$D18+K44*$D43+K129*$D128)/$D8) | L9: =IF($D8=0,0,(L14*$D13+L19*$D18+L44*$D43+L129*$D128)/$D8) | M9: =IF($D8=0,0,(M14*$D13+M19*$D18+M44*$D43+M129*$D128)/$D8) | N9: =IF($D8=0,0,(N14*$D13+N19*$D18+N44*$D43+N129*$D128)/$D8) | O9: =IF($D8=0,0,(O14*$D13+O19*$D18+O44*$D43+O129*$D128)/$D8) | ... AC9: =IF($D8=0,0,(AC14*$D13+AC19*$D18+AC44*$D43+AC129*$D128)/$D8)
C10: 累計出来高率 | H10: =H9 | I10: =H10+I9 | J10: =I10+J9 | K10: =J10+K9 | L10: =K10+L9 | M10: =L10+M9 | N10: =M10+N9 | O10: =N10+O9 | P10: =O10+P9 | ... AC10: =AB10+AC9
C11: 今週出来高金額 | H11: =H16+H21+H46+H131 | I11: =I16+I21+I46+I131 | J11: =J16+J21+J46+J131 | K11: =K16+K21+K46+K131 | L11: =L16+L21+L46+L131 | M11: =M16+M21+M46+M131 | N11: =N16+N21+N46+N131 | O11: =O16+O21+O46+O131 | ... AC11: =AC16+AC21+AC46+AC131
C12: 累計出来高金額 | H12: =H11 | I12: =H12+I11 | J12: =I12+J11 | K12: =J12+K11 | L12: =K12+L11 | M12: =L12+M11 | N12: =M12+N11 | O12: =N12+O11 | P12: =O12+P11 | ... AC12: =AB12+AC11
A13: a) | B13: 共通仮設工事 | C13: 工程 | D13: ='金額リスト'!C6 | E13: =SUMPRODUCT((H13:AC13<>"")*(H$6:AC$6=1)) | F13: =SUM(H14:AC14) | G13: =IF(AND(ABS(F13-1)<0.0001,ABS(AC15-1)<0.0001),"OK",IF(E13=0,"工程未設定","NG")) | I13: 1 | J13: 1 | K13: 1 | L13: 1 | M13: 1 | N13: 1 | O13: 1 | P13: 1 | Q13: 1 | R13: 1 | S13: 1 | T13: 1 | U13: 1 | V13: 1 | W13: 1 | X13: 1 | Y13: 1 | Z13: 1 | AA13: 1 | AB13: 1 | AC13: 1
C14: 今週出来高率 | H14: =IF(OR($E13=0,H13="",H$6<>1),0,1/$E13) | I14: =IF(OR($E13=0,I13="",I$6<>1),0,1/$E13) | J14: =IF(OR($E13=0,J13="",J$6<>1),0,1/$E13) | K14: =IF(OR($E13=0,K13="",K$6<>1),0,1/$E13) | L14: =IF(OR($E13=0,L13="",L$6<>1),0,1/$E13) | M14: =IF(OR($E13=0,M13="",M$6<>1),0,1/$E13) | N14: =IF(OR($E13=0,N13="",N$6<>1),0,1/$E13) | O14: =IF(OR($E13=0,O13="",O$6<>1),0,1/$E13) | ... AC14: =IF(OR($E13=0,AC13="",AC$6<>1),0,1/$E13)
C15: 累計出来高率 | H15: =H14 | I15: =H15+I14 | J15: =I15+J14 | K15: =J15+K14 | L15: =K15+L14 | M15: =L15+M14 | N15: =M15+N14 | O15: =N15+O14 | P15: =O15+P14 | ... AC15: =AB15+AC14
C16: 今週出来高金額 | H16: =H14*$D13 | I16: =I14*$D13 | J16: =J14*$D13 | K16: =K14*$D13 | L16: =L14*$D13 | M16: =M14*$D13 | N16: =N14*$D13 | O16: =O14*$D13 | ... AC16: =AC14*$D13
C17: 累計出来高金額 | H17: =H16 | I17: =H17+I16 | J17: =I17+J16 | K17: =J17+K16 | L17: =K17+L16 | M17: =L17+M16 | N17: =M17+N16 | O17: =N17+O16 | P17: =O17+P16 | ... AC17: =AB17+AC16
A18: b) | B18: 解体撤去工事 | C18: 工程 | D18: =D23+D28+D33+D38 | E18: =COUNTIF(H19:AC19,">0") | F18: =SUM(H19:AC19) | G18: =IF(AND(ABS(F18-1)<0.0001,ABS(AC20-1)<0.0001),"OK",IF(E18=0,"工程未設定","NG")) | H18: =IF(H19>0,"■","") | I18: =IF(I19>0,"■","") | J18: =IF(J19>0,"■","") | K18: =IF(K19>0,"■","") | L18: =IF(L19>0,"■","") | M18: =IF(M19>0,"■","") | N18: =IF(N19>0,"■","") | O18: =IF(O19>0,"■","") | ... AC18: =IF(AC19>0,"■","")
C19: 今週出来高率 | H19: =IF($D18=0,0,(H24*$D23+H29*$D28+H34*$D33+H39*$D38)/$D18) | I19: =IF($D18=0,0,(I24*$D23+I29*$D28+I34*$D33+I39*$D38)/$D18) | J19: =IF($D18=0,0,(J24*$D23+J29*$D28+J34*$D33+J39*$D38)/$D18) | K19: =IF($D18=0,0,(K24*$D23+K29*$D28+K34*$D33+K39*$D38)/$D18) | L19: =IF($D18=0,0,(L24*$D23+L29*$D28+L34*$D33+L39*$D38)/$D18) | M19: =IF($D18=0,0,(M24*$D23+M29*$D28+M34*$D33+M39*$D38)/$D18) | N19: =IF($D18=0,0,(N24*$D23+N29*$D28+N34*$D33+N39*$D38)/$D18) | O19: =IF($D18=0,0,(O24*$D23+O29*$D28+O34*$D33+O39*$D38)/$D18) | ... AC19: =IF($D18=0,0,(AC24*$D23+AC29*$D28+AC34*$D33+AC39*$D38)/$D18)
C20: 累計出来高率 | H20: =H19 | I20: =H20+I19 | J20: =I20+J19 | K20: =J20+K19 | L20: =K20+L19 | M20: =L20+M19 | N20: =M20+N19 | O20: =N20+O19 | P20: =O20+P19 | ... AC20: =AB20+AC19
C21: 今週出来高金額 | H21: =H26+H31+H36+H41 | I21: =I26+I31+I36+I41 | J21: =J26+J31+J36+J41 | K21: =K26+K31+K36+K41 | L21: =L26+L31+L36+L41 | M21: =M26+M31+M36+M41 | N21: =N26+N31+N36+N41 | O21: =O26+O31+O36+O41 | ... AC21: =AC26+AC31+AC36+AC41
C22: 累計出来高金額 | H22: =H21 | I22: =H22+I21 | J22: =I22+J21 | K22: =J22+K21 | L22: =K22+L21 | M22: =L22+M21 | N22: =M22+N21 | O22: =N22+O21 | P22: =O22+P21 | ... AC22: =AB22+AC21
A23: b)-1 | B23: 建築工事 | C23: 工程 | D23: ='金額リスト'!C8 | E23: =SUMPRODUCT((H23:AC23<>"")*(H$6:AC$6=1)) | F23: =SUM(H24:AC24) | G23: =IF(AND(ABS(F23-1)<0.0001,ABS(AC25-1)<0.0001),"OK",IF(E23=0,"工程未設定","NG")) | I23: 1 | J23: 1 | K23: 1 | M23: 1 | O23: 1
C24: 今週出来高率 | H24: =IF(OR($E23=0,H23="",H$6<>1),0,1/$E23) | I24: =IF(OR($E23=0,I23="",I$6<>1),0,1/$E23) | J24: =IF(OR($E23=0,J23="",J$6<>1),0,1/$E23) | K24: =IF(OR($E23=0,K23="",K$6<>1),0,1/$E23) | L24: =IF(OR($E23=0,L23="",L$6<>1),0,1/$E23) | M24: =IF(OR($E23=0,M23="",M$6<>1),0,1/$E23) | N24: =IF(OR($E23=0,N23="",N$6<>1),0,1/$E23) | O24: =IF(OR($E23=0,O23="",O$6<>1),0,1/$E23) | ... AC24: =IF(OR($E23=0,AC23="",AC$6<>1),0,1/$E23)
C25: 累計出来高率 | H25: =H24 | I25: =H25+I24 | J25: =I25+J24 | K25: =J25+K24 | L25: =K25+L24 | M25: =L25+M24 | N25: =M25+N24 | O25: =N25+O24 | P25: =O25+P24 | ... AC25: =AB25+AC24
C26: 今週出来高金額 | H26: =H24*$D23 | I26: =I24*$D23 | J26: =J24*$D23 | K26: =K24*$D23 | L26: =L24*$D23 | M26: =M24*$D23 | N26: =N24*$D23 | O26: =O24*$D23 | ... AC26: =AC24*$D23
C27: 累計出来高金額 | H27: =H26 | I27: =H27+I26 | J27: =I27+J26 | K27: =J27+K26 | L27: =K27+L26 | M27: =L27+M26 | N27: =M27+N26 | O27: =N27+O26 | P27: =O27+P26 | ... AC27: =AB27+AC26
B28: 電気設備工事 | C28: 工程 | D28: ='金額リスト'!C10 | E28: =SUMPRODUCT((H28:AC28<>"")*(H$6:AC$6=1)) | F28: =SUM(H29:AC29) | G28: =IF(AND(ABS(F28-1)<0.0001,ABS(AC30-1)<0.0001),"OK",IF(E28=0,"工程未設定","NG")) | I28: 1 | L28: 1 | M28: 1
C29: 今週出来高率 | H29: =IF(OR($E28=0,H28="",H$6<>1),0,1/$E28) | I29: =IF(OR($E28=0,I28="",I$6<>1),0,1/$E28) | J29: =IF(OR($E28=0,J28="",J$6<>1),0,1/$E28) | K29: =IF(OR($E28=0,K28="",K$6<>1),0,1/$E28) | L29: =IF(OR($E28=0,L28="",L$6<>1),0,1/$E28) | M29: =IF(OR($E28=0,M28="",M$6<>1),0,1/$E28) | N29: =IF(OR($E28=0,N28="",N$6<>1),0,1/$E28) | O29: =IF(OR($E28=0,O28="",O$6<>1),0,1/$E28) | ... AC29: =IF(OR($E28=0,AC28="",AC$6<>1),0,1/$E28)
C30: 累計出来高率 | H30: =H29 | I30: =H30+I29 | J30: =I30+J29 | K30: =J30+K29 | L30: =K30+L29 | M30: =L30+M29 | N30: =M30+N29 | O30: =N30+O29 | P30: =O30+P29 | ... AC30: =AB30+AC29
C31: 今週出来高金額 | H31: =H29*$D28 | I31: =I29*$D28 | J31: =J29*$D28 | K31: =K29*$D28 | L31: =L29*$D28 | M31: =M29*$D28 | N31: =N29*$D28 | O31: =O29*$D28 | ... AC31: =AC29*$D28
C32: 累計出来高金額 | H32: =H31 | I32: =H32+I31 | J32: =I32+J31 | K32: =J32+K31 | L32: =K32+L31 | M32: =L32+M31 | N32: =M32+N31 | O32: =N32+O31 | P32: =O32+P31 | ... AC32: =AB32+AC31
B33: 空気調和設備工事 | C33: 工程 | D33: ='金額リスト'!C11 | E33: =SUMPRODUCT((H33:AC33<>"")*(H$6:AC$6=1)) | F33: =SUM(H34:AC34) | G33: =IF(AND(ABS(F33-1)<0.0001,ABS(AC35-1)<0.0001),"OK",IF(E33=0,"工程未設定","NG")) | I33: 1 | L33: 1 | M33: 1
C34: 今週出来高率 | H34: =IF(OR($E33=0,H33="",H$6<>1),0,1/$E33) | I34: =IF(OR($E33=0,I33="",I$6<>1),0,1/$E33) | J34: =IF(OR($E33=0,J33="",J$6<>1),0,1/$E33) | K34: =IF(OR($E33=0,K33="",K$6<>1),0,1/$E33) | L34: =IF(OR($E33=0,L33="",L$6<>1),0,1/$E33) | M34: =IF(OR($E33=0,M33="",M$6<>1),0,1/$E33) | N34: =IF(OR($E33=0,N33="",N$6<>1),0,1/$E33) | O34: =IF(OR($E33=0,O33="",O$6<>1),0,1/$E33) | ... AC34: =IF(OR($E33=0,AC33="",AC$6<>1),0,1/$E33)
C35: 累計出来高率 | H35: =H34 | I35: =H35+I34 | J35: =I35+J34 | K35: =J35+K34 | L35: =K35+L34 | M35: =L35+M34 | N35: =M35+N34 | O35: =N35+O34 | P35: =O35+P34 | ... AC35: =AB35+AC34
C36: 今週出来高金額 | H36: =H34*$D33 | I36: =I34*$D33 | J36: =J34*$D33 | K36: =K34*$D33 | L36: =L34*$D33 | M36: =M34*$D33 | N36: =N34*$D33 | O36: =O34*$D33 | ... AC36: =AC34*$D33
C37: 累計出来高金額 | H37: =H36 | I37: =H37+I36 | J37: =I37+J36 | K37: =J37+K36 | L37: =K37+L36 | M37: =L37+M36 | N37: =M37+N36 | O37: =N37+O36 | P37: =O37+P36 | ... AC37: =AB37+AC36
B38: 衛生設備工事 | C38: 工程 | D38: ='金額リスト'!C12 | E38: =SUMPRODUCT((H38:AC38<>"")*(H$6:AC$6=1)) | F38: =SUM(H39:AC39) | G38: =IF(AND(ABS(F38-1)<0.0001,ABS(AC40-1)<0.0001),"OK",IF(E38=0,"工程未設定","NG")) | I38: 1 | L38: 1 | M38: 1
C39: 今週出来高率 | H39: =IF(OR($E38=0,H38="",H$6<>1),0,1/$E38) | I39: =IF(OR($E38=0,I38="",I$6<>1),0,1/$E38) | J39: =IF(OR($E38=0,J38="",J$6<>1),0,1/$E38) | K39: =IF(OR($E38=0,K38="",K$6<>1),0,1/$E38) | L39: =IF(OR($E38=0,L38="",L$6<>1),0,1/$E38) | M39: =IF(OR($E38=0,M38="",M$6<>1),0,1/$E38) | N39: =IF(OR($E38=0,N38="",N$6<>1),0,1/$E38) | O39: =IF(OR($E38=0,O38="",O$6<>1),0,1/$E38) | ... AC39: =IF(OR($E38=0,AC38="",AC$6<>1),0,1/$E38)
C40: 累計出来高率 | H40: =H39 | I40: =H40+I39 | J40: =I40+J39 | K40: =J40+K39 | L40: =K40+L39 | M40: =L40+M39 | N40: =M40+N39 | O40: =N40+O39 | P40: =O40+P39 | ... AC40: =AB40+AC39
...

Sheet 月別出来高
A1: 月別 予想出来高（予想出来高率・予想出来高金額）
A2: 予想値（実績ではありません）。「週間出来高」シートの各週を計上月（同シート7行目）ごとに集計。月をまたぐ週は月曜の属する月に計上。
A4: 項 | B4: 名称 | C4: 区分 | D4: 契約金額（円） | E4: 11月 | F4: 12月 | G4: 1月 | H4: 2月 | I4: 3月 | J4: 計 | K4: 100%チェック
B5: 工事費 合計（税抜） | C5: 月出来高率 | D5: ='週間出来高'!D8 | E5: =SUMPRODUCT(('週間出来高'!$H$7:$AC$7=11)*'週間出来高'!$H$9:$AC$9) | F5: =SUMPRODUCT(('週間出来高'!$H$7:$AC$7=12)*'週間出来高'!$H$9:$AC$9) | G5: =SUMPRODUCT(('週間出来高'!$H$7:$AC$7=1)*'週間出来高'!$H$9:$AC$9) | H5: =SUMPRODUCT(('週間出来高'!$H$7:$AC$7=2)*'週間出来高'!$H$9:$AC$9) | I5: =SUMPRODUCT(('週間出来高'!$H$7:$AC$7=3)*'週間出来高'!$H$9:$AC$9) | J5: =SUM(E5:I5) | K5: =IF(AND(ABS(J5-1)<0.0001,ABS(J7-D5)<1),"OK","NG")
C6: 累計出来高率 | E6: =E5 | F6: =E6+F5 | G6: =F6+G5 | H6: =G6+H5 | I6: =H6+I5 | J6: =I6
C7: 月出来高金額 | E7: =SUMPRODUCT(('週間出来高'!$H$7:$AC$7=11)*'週間出来高'!$H$11:$AC$11) | F7: =SUMPRODUCT(('週間出来高'!$H$7:$AC$7=12)*'週間出来高'!$H$11:$AC$11) | G7: =SUMPRODUCT(('週間出来高'!$H$7:$AC$7=1)*'週間出来高'!$H$11:$AC$11) | H7: =SUMPRODUCT(('週間出来高'!$H$7:$AC$7=2)*'週間出来高'!$H$11:$AC$11) | I7: =SUMPRODUCT(('週間出来高'!$H$7:$AC$7=3)*'週間出来高'!$H$11:$AC$11) | J7: =SUM(E7:I7)
A8: a) | B8: 共通仮設工事 | C8: 月出来高率 | D8: ='週間出来高'!D13 | E8: =SUMPRODUCT(('週間出来高'!$H$7:$AC$7=11)*'週間出来高'!$H$14:$AC$14) | F8: =SUMPRODUCT(('週間出来高'!$H$7:$AC$7=12)*'週間出来高'!$H$14:$AC$14) | G8: =SUMPRODUCT(('週間出来高'!$H$7:$AC$7=1)*'週間出来高'!$H$14:$AC$14) | H8: =SUMPRODUCT(('週間出来高'!$H$7:$AC$7=2)*'週間出来高'!$H$14:$AC$14) | I8: =SUMPRODUCT(('週間出来高'!$H$7:$AC$7=3)*'週間出来高'!$H$14:$AC$14) | J8: =SUM(E8:I8) | K8: =IF(AND(ABS(J8-1)<0.0001,ABS(J10-D8)<1),"OK","NG")
C9: 累計出来高率 | E9: =E8 | F9: =E9+F8 | G9: =F9+G8 | H9: =G9+H8 | I9: =H9+I8 | J9: =I9
C10: 月出来高金額 | E10: =SUMPRODUCT(('週間出来高'!$H$7:$AC$7=11)*'週間出来高'!$H$16:$AC$16) | F10: =SUMPRODUCT(('週間出来高'!$H$7:$AC$7=12)*'週間出来高'!$H$16:$AC$16) | G10: =SUMPRODUCT(('週間出来高'!$H$7:$AC$7=1)*'週間出来高'!$H$16:$AC$16) | H10: =SUMPRODUCT(('週間出来高'!$H$7:$AC$7=2)*'週間出来高'!$H$16:$AC$16) | I10: =SUMPRODUCT(('週間出来高'!$H$7:$AC$7=3)*'週間出来高'!$H$16:$AC$16) | J10: =SUM(E10:I10)
A11: b) | B11: 解体撤去工事 | C11: 月出来高率 | D11: ='週間出来高'!D18 | E11: =SUMPRODUCT(('週間出来高'!$H$7:$AC$7=11)*'週間出来高'!$H$19:$AC$19) | F11: =SUMPRODUCT(('週間出来高'!$H$7:$AC$7=12)*'週間出来高'!$H$19:$AC$19) | G11: =SUMPRODUCT(('週間出来高'!$H$7:$AC$7=1)*'週間出来高'!$H$19:$AC$19) | H11: =SUMPRODUCT(('週間出来高'!$H$7:$AC$7=2)*'週間出来高'!$H$19:$AC$19) | I11: =SUMPRODUCT(('週間出来高'!$H$7:$AC$7=3)*'週間出来高'!$H$19:$AC$19) | J11: =SUM(E11:I11) | K11: =IF(AND(ABS(J11-1)<0.0001,ABS(J13-D11)<1),"OK","NG")
C12: 累計出来高率 | E12: =E11 | F12: =E12+F11 | G12: =F12+G11 | H12: =G12+H11 | I12: =H12+I11 | J12: =I12
C13: 月出来高金額 | E13: =SUMPRODUCT(('週間出来高'!$H$7:$AC$7=11)*'週間出来高'!$H$21:$AC$21) | F13: =SUMPRODUCT(('週間出来高'!$H$7:$AC$7=12)*'週間出来高'!$H$21:$AC$21) | G13: =SUMPRODUCT(('週間出来高'!$H$7:$AC$7=1)*'週間出来高'!$H$21:$AC$21) | H13: =SUMPRODUCT(('週間出来高'!$H$7:$AC$7=2)*'週間出来高'!$H$21:$AC$21) | I13: =SUMPRODUCT(('週間出来高'!$H$7:$AC$7=3)*'週間出来高'!$H$21:$AC$21) | J13: =SUM(E13:I13)
A14: b)-1 | B14: 建築工事 | C14: 月出来高率 | D14: ='週間出来高'!D23 | E14: =SUMPRODUCT(('週間出来高'!$H$7:$AC$7=11)*'週間出来高'!$H$24:$AC$24) | F14: =SUMPRODUCT(('週間出来高'!$H$7:$AC$7=12)*'週間出来高'!$H$24:$AC$24) | G14: =SUMPRODUCT(('週間出来高'!$H$7:$AC$7=1)*'週間出来高'!$H$24:$AC$24) | H14: =SUMPRODUCT(('週間出来高'!$H$7:$AC$7=2)*'週間出来高'!$H$24:$AC$24) | I14: =SUMPRODUCT(('週間出来高'!$H$7:$AC$7=3)*'週間出来高'!$H$24:$AC$24) | J14: =SUM(E14:I14) | K14: =IF(AND(ABS(J14-1)<0.0001,ABS(J16-D14)<1),"OK","NG")
C15: 累計出来高率 | E15: =E14 | F15: =E15+F14 | G15: =F15+G14 | H15: =G15+H14 | I15: =H15+I14 | J15: =I15
C16: 月出来高金額 | E16: =SUMPRODUCT(('週間出来高'!$H$7:$AC$7=11)*'週間出来高'!$H$26:$AC$26) | F16: =SUMPRODUCT(('週間出来高'!$H$7:$AC$7=12)*'週間出来高'!$H$26:$AC$26) | G16: =SUMPRODUCT(('週間出来高'!$H$7:$AC$7=1)*'週間出来高'!$H$26:$AC$26) | H16: =SUMPRODUCT(('週間出来高'!$H$7:$AC$7=2)*'週間出来高'!$H$26:$AC$26) | I16: =SUMPRODUCT(('週間出来高'!$H$7:$AC$7=3)*'週間出来高'!$H$26:$AC$26) | J16: =SUM(E16:I16)
B17: 電気設備工事 | C17: 月出来高率 | D17: ='週間出来高'!D28 | E17: =SUMPRODUCT(('週間出来高'!$H$7:$AC$7=11)*'週間出来高'!$H$29:$AC$29) | F17: =SUMPRODUCT(('週間出来高'!$H$7:$AC$7=12)*'週間出来高'!$H$29:$AC$29) | G17: =SUMPRODUCT(('週間出来高'!$H$7:$AC$7=1)*'週間出来高'!$H$29:$AC$29) | H17: =SUMPRODUCT(('週間出来高'!$H$7:$AC$7=2)*'週間出来高'!$H$29:$AC$29) | I17: =SUMPRODUCT(('週間出来高'!$H$7:$AC$7=3)*'週間出来高'!$H$29:$AC$29) | J17: =SUM(E17:I17) | K17: =IF(AND(ABS(J17-1)<0.0001,ABS(J19-D17)<1),"OK","NG")
C18: 累計出来高率 | E18: =E17 | F18: =E18+F17 | G18: =F18+G17 | H18: =G18+H17 | I18: =H18+I17 | J18: =I18
C19: 月出来高金額 | E19: =SUMPRODUCT(('週間出来高'!$H$7:$AC$7=11)*'週間出来高'!$H$31:$AC$31) | F19: =SUMPRODUCT(('週間出来高'!$H$7:$AC$7=12)*'週間出来高'!$H$31:$AC$31) | G19: =SUMPRODUCT(('週間出来高'!$H$7:$AC$7=1)*'週間出来高'!$H$31:$AC$31) | H19: =SUMPRODUCT(('週間出来高'!$H$7:$AC$7=2)*'週間出来高'!$H$31:$AC$31) | I19: =SUMPRODUCT(('週間出来高'!$H$7:$AC$7=3)*'週間出来高'!$H$31:$AC$31) | J19: =SUM(E19:I19)
B20: 空気調和設備工事 | C20: 月出来高率 | D20: ='週間出来高'!D33 | E20: =SUMPRODUCT(('週間出来高'!$H$7:$AC$7=11)*'週間出来高'!$H$34:$AC$34) | F20: =SUMPRODUCT(('週間出来高'!$H$7:$AC$7=12)*'週間出来高'!$H$34:$AC$34) | G20: =SUMPRODUCT(('週間出来高'!$H$7:$AC$7=1)*'週間出来高'!$H$34:$AC$34) | H20: =SUMPRODUCT(('週間出来高'!$H$7:$AC$7=2)*'週間出来高'!$H$34:$AC$34) | I20: =SUMPRODUCT(('週間出来高'!$H$7:$AC$7=3)*'週間出来高'!$H$34:$AC$34) | J20: =SUM(E20:I20) | K20: =IF(AND(ABS(J20-1)<0.0001,ABS(J22-D20)<1),"OK","NG")
C21: 累計出来高率 | E21: =E20 | F21: =E21+F20 | G21: =F21+G20 | H21: =G21+H20 | I21: =H21+I20 | J21: =I21
C22: 月出来高金額 | E22: =SUMPRODUCT(('週間出来高'!$H$7:$AC$7=11)*'週間出来高'!$H$36:$AC$36) | F22: =SUMPRODUCT(('週間出来高'!$H$7:$AC$7=12)*'週間出来高'!$H$36:$AC$36) | G22: =SUMPRODUCT(('週間出来高'!$H$7:$AC$7=1)*'週間出来高'!$H$36:$AC$36) | H22: =SUMPRODUCT(('週間出来高'!$H$7:$AC$7=2)*'週間出来高'!$H$36:$AC$36) | I22: =SUMPRODUCT(('週間出来高'!$H$7:$AC$7=3)*'週間出来高'!$H$36:$AC$36) | J22: =SUM(E22:I22)
B23: 衛生設備工事 | C23: 月出来高率 | D23: ='週間出来高'!D38 | E23: =SUMPRODUCT(('週間出来高'!$H$7:$AC$7=11)*'週間出来高'!$H$39:$AC$39) | F23: =SUMPRODUCT(('週間出来高'!$H$7:$AC$7=12)*'週間出来高'!$H$39:$AC$39) | G23: =SUMPRODUCT(('週間出来高'!$H$7:$AC$7=1)*'週間出来高'!$H$39:$AC$39) | H23: =SUMPRODUCT(('週間出来高'!$H$7:$AC$7=2)*'週間出来高'!$H$39:$AC$39) | I23: =SUMPRODUCT(('週間出来高'!$H$7:$AC$7=3)*'週間出来高'!$H$39:$AC$39) | J23: =SUM(E23:I23) | K23: =IF(AND(ABS(J23-1)<0.0001,ABS(J25-D23)<1),"OK","NG")
C24: 累計出来高率 | E24: =E23 | F24: =E24+F23 | G24: =F24+G23 | H24: =G24+H23 | I24: =H24+I23 | J24: =I24
C25: 月出来高金額 | E25: =SUMPRODUCT(('週間出来高'!$H$7:$AC$7=11)*'週間出来高'!$H$41:$AC$41) | F25: =SUMPRODUCT(('週間出来高'!$H$7:$AC$7=12)*'週間出来高'!$H$41:$AC$41) | G25: =SUMPRODUCT(('週間出来高'!$H$7:$AC$7=1)*'週間出来高'!$H$41:$AC$41) | H25: =SUMPRODUCT(('週間出来高'!$H$7:$AC$7=2)*'週間出来高'!$H$41:$AC$41) | I25: =SUMPRODUCT(('週間出来高'!$H$7:$AC$7=3)*'週間出来高'!$H$41:$AC$41) | J25: =SUM(E25:I25)
A26: c) | B26: 改修工事 | C26: 月出来高率 | D26: ='週間出来高'!D43 | E26: =SUMPRODUCT(('週間出来高'!$H$7:$AC$7=11)*'週間出来高'!$H$44:$AC$44) | F26: =SUMPRODUCT(('週間出来高'!$H$7:$AC$7=12)*'週間出来高'!$H$44:$AC$44) | G26: =SUMPRODUCT(('週間出来高'!$H$7:$AC$7=1)*'週間出来高'!$H$44:$AC$44) | H26: =SUMPRODUCT(('週間出来高'!$H$7:$AC$7=2)*'週間出来高'!$H$44:$AC$44) | I26: =SUMPRODUCT(('週間出来高'!$H$7:$AC$7=3)*'週間出来高'!$H$44:$AC$44) | J26: =SUM(E26:I26) | K26: =IF(AND(ABS(J26-1)<0.0001,ABS(J28-D26)<1),"OK","NG")
C27: 累計出来高率 | E27: =E26 | F27: =E27+F26 | G27: =F27+G26 | H27: =G27+H26 | I27: =H27+I26 | J27: =I27
C28: 月出来高金額 | E28: =SUMPRODUCT(('週間出来高'!$H$7:$AC$7=11)*'週間出来高'!$H$46:$AC$46) | F28: =SUMPRODUCT(('週間出来高'!$H$7:$AC$7=12)*'週間出来高'!$H$46:$AC$46) | G28: =SUMPRODUCT(('週間出来高'!$H$7:$AC$7=1)*'週間出来高'!$H$46:$AC$46) | H28: =SUMPRODUCT(('週間出来高'!$H$7:$AC$7=2)*'週間出来高'!$H$46:$AC$46) | I28: =SUMPRODUCT(('週間出来高'!$H$7:$AC$7=3)*'週間出来高'!$H$46:$AC$46) | J28: =SUM(E28:I28)
A29: c)-1 | B29: 建築工事 | C29: 月出来高率 | D29: ='週間出来高'!D48 | E29: =SUMPRODUCT(('週間出来高'!$H$7:$AC$7=11)*'週間出来高'!$H$49:$AC$49) | F29: =SUMPRODUCT(('週間出来高'!$H$7:$AC$7=12)*'週間出来高'!$H$49:$AC$49) | G29: =SUMPRODUCT(('週間出来高'!$H$7:$AC$7=1)*'週間出来高'!$H$49:$AC$49) | H29: =SUMPRODUCT(('週間出来高'!$H$7:$AC$7=2)*'週間出来高'!$H$49:$AC$49) | I29: =SUMPRODUCT(('週間出来高'!$H$7:$AC$7=3)*'週間出来高'!$H$49:$AC$49) | J29: =SUM(E29:I29) | K29: =IF(AND(ABS(J29-1)<0.0001,ABS(J31-D29)<1),"OK","NG")
C30: 累計出来高率 | E30: =E29 | F30: =E30+F29 | G30: =F30+G29 | H30: =G30+H29 | I30: =H30+I29 | J30: =I30
C31: 月出来高金額 | E31: =SUMPRODUCT(('週間出来高'!$H$7:$AC$7=11)*'週間出来高'!$H$51:$AC$51) | F31: =SUMPRODUCT(('週間出来高'!$H$7:$AC$7=12)*'週間出来高'!$H$51:$AC$51) | G31: =SUMPRODUCT(('週間出来高'!$H$7:$AC$7=1)*'週間出来高'!$H$51:$AC$51) | H31: =SUMPRODUCT(('週間出来高'!$H$7:$AC$7=2)*'週間出来高'!$H$51:$AC$51) | I31: =SUMPRODUCT(('週間出来高'!$H$7:$AC$7=3)*'週間出来高'!$H$51:$AC$51) | J31: =SUM(E31:I31)
A32: 1 | B32: 直接仮設工事 | C32: 月出来高率 | D32: ='週間出来高'!D53 | E32: =SUMPRODUCT(('週間出来高'!$H$7:$AC$7=11)*'週間出来高'!$H$54:$AC$54) | F32: =SUMPRODUCT(('週間出来高'!$H$7:$AC$7=12)*'週間出来高'!$H$54:$AC$54) | G32: =SUMPRODUCT(('週間出来高'!$H$7:$AC$7=1)*'週間出来高'!$H$54:$AC$54) | H32: =SUMPRODUCT(('週間出来高'!$H$7:$AC$7=2)*'週間出来高'!$H$54:$AC$54) | I32: =SUMPRODUCT(('週間出来高'!$H$7:$AC$7=3)*'週間出来高'!$H$54:$AC$54) | J32: =SUM(E32:I32) | K32: =IF(AND(ABS(J32-1)<0.0001,ABS(J34-D32)<1),"OK","NG")
C33: 累計出来高率 | E33: =E32 | F33: =E33+F32 | G33: =F33+G32 | H33: =G33+H32 | I33: =H33+I32 | J33: =I33
C34: 月出来高金額 | E34: =SUMPRODUCT(('週間出来高'!$H$7:$AC$7=11)*'週間出来高'!$H$56:$AC$56) | F34: =SUMPRODUCT(('週間出来高'!$H$7:$AC$7=12)*'週間出来高'!$H$56:$AC$56) | G34: =SUMPRODUCT(('週間出来高'!$H$7:$AC$7=1)*'週間出来高'!$H$56:$AC$56) | H34: =SUMPRODUCT(('週間出来高'!$H$7:$AC$7=2)*'週間出来高'!$H$56:$AC$56) | I34: =SUMPRODUCT(('週間出来高'!$H$7:$AC$7=3)*'週間出来高'!$H$56:$AC$56) | J34: =SUM(E34:I34)
A35: 2 | B35: 躯体工事 | C35: 月出来高率 | D35: ='週間出来高'!D58 | E35: =SUMPRODUCT(('週間出来高'!$H$7:$AC$7=11)*'週間出来高'!$H$59:$AC$59) | F35: =SUMPRODUCT(('週間出来高'!$H$7:$AC$7=12)*'週間出来高'!$H$59:$AC$59) | G35: =SUMPRODUCT(('週間出来高'!$H$7:$AC$7=1)*'週間出来高'!$H$59:$AC$59) | H35: =SUMPRODUCT(('週間出来高'!$H$7:$AC$7=2)*'週間出来高'!$H$59:$AC$59) | I35: =SUMPRODUCT(('週間出来高'!$H$7:$AC$7=3)*'週間出来高'!$H$59:$AC$59) | J35: =SUM(E35:I35) | K35: =IF(AND(ABS(J35-1)<0.0001,ABS(J37-D35)<1),"OK","NG")
C36: 累計出来高率 | E36: =E35 | F36: =E36+F35 | G36: =F36+G35 | H36: =G36+H35 | I36: =H36+I35 | J36: =I36
C37: 月出来高金額 | E37: =SUMPRODUCT(('週間出来高'!$H$7:$AC$7=11)*'週間出来高'!$H$61:$AC$61) | F37: =SUMPRODUCT(('週間出来高'!$H$7:$AC$7=12)*'週間出来高'!$H$61:$AC$61) | G37: =SUMPRODUCT(('週間出来高'!$H$7:$AC$7=1)*'週間出来高'!$H$61:$AC$61) | H37: =SUMPRODUCT(('週間出来高'!$H$7:$AC$7=2)*'週間出来高'!$H$61:$AC$61) | I37: =SUMPRODUCT(('週間出来高'!$H$7:$AC$7=3)*'週間出来高'!$H$61:$AC$61) | J37: =SUM(E37:I37)
A38: 3 | B38: 防水工事 | C38: 月出来高率 | D38: ='週間出来高'!D63 | E38: =SUMPRODUCT(('週間出来高'!$H$7:$AC$7=11)*'週間出来高'!$H$64:$AC$64) | F38: =SUMPRODUCT(('週間出来高'!$H$7:$AC$7=12)*'週間出来高'!$H$64:$AC$64) | G38: =SUMPRODUCT(('週間出来高'!$H$7:$AC$7=1)*'週間出来高'!$H$64:$AC$64) | H38: =SUMPRODUCT(('週間出来高'!$H$7:$AC$7=2)*'週間出来高'!$H$64:$AC$64) | I38: =SUMPRODUCT(('週間出来高'!$H$7:$AC$7=3)*'週間出来高'!$H$64:$AC$64) | J38: =SUM(E38:I38) | K38: =IF(AND(ABS(J38-1)<0.0001,ABS(J40-D38)<1),"OK","NG")
C39: 累計出来高率 | E39: =E38 | F39: =E39+F38 | G39: =F39+G38 | H39: =G39+H38 | I39: =H39+I38 | J39: =I39
C40: 月出来高金額 | E40: =SUMPRODUCT(('週間出来高'!$H$7:$AC$7=11)*'週間出来高'!$H$66:$AC$66) | F40: =SUMPRODUCT(('週間出来高'!$H$7:$AC$7=12)*'週間出来高'!$H$66:$AC$66) | G40: =SUMPRODUCT(('週間出来高'!$H$7:$AC$7=1)*'週間出来高'!$H$66:$AC$66) | H40: =SUMPRODUCT(('週間出来高'!$H$7:$AC$7=2)*'週間出来高'!$H$66:$AC$66) | I40: =SUMPRODUCT(('週間出来高'!$H$7:$AC$7=3)*'週間出来高'!$H$66:$AC$66) | J40: =SUM(E40:I40)
A41: 4 | B41: タイル工事 | C41: 月出来高率 | D41: ='週間出来高'!D68 | E41: =SUMPRODUCT(('週間出来高'!$H$7:$AC$7=11)*'週間出来高'!$H$69:$AC$69) | F41: =SUMPRODUCT(('週間出来高'!$H$7:$AC$7=12)*'週間出来高'!$H$69:$AC$69) | G41: =SUMPRODUCT(('週間出来高'!$H$7:$AC$7=1)*'週間出来高'!$H$69:$AC$69) | H41: =SUMPRODUCT(('週間出来高'!$H$7:$AC$7=2)*'週間出来高'!$H$69:$AC$69) | I41: =SUMPRODUCT(('週間出来高'!$H$7:$AC$7=3)*'週間出来高'!$H$69:$AC$69) | J41: =SUM(E41:I41) | K41: =IF(AND(ABS(J41-1)<0.0001,ABS(J43-D41)<1),"OK","NG")
...

Sheet 出来高曲線
A1: 予想工事進捗グラフ（予想出来高曲線・Sカーブ）
A2: 予想値（実績ではありません）。縦軸：出来高率（棒＝各期の出来高率、線＝累計出来高率＝Sカーブ）／横軸：週・月。工事費合計行を参照（金額加重）。
A4: 期間 | B4: 出来高金額（円） | C4: 累計出来高金額（円） | D4: 出来高率 | E4: 累計出来高率
A5: 着工前 | B5: 0 | C5: 0 | D5: 0 | E5: 0
A6: 11月1週 | B6: ='週間出来高'!H11 | C6: ='週間出来高'!H12 | D6: ='週間出来高'!H9 | E6: ='週間出来高'!H10
A7: 11月2週 | B7: ='週間出来高'!I11 | C7: ='週間出来高'!I12 | D7: ='週間出来高'!I9 | E7: ='週間出来高'!I10
A8: 11月3週 | B8: ='週間出来高'!J11 | C8: ='週間出来高'!J12 | D8: ='週間出来高'!J9 | E8: ='週間出来高'!J10
A9: 11月4週 | B9: ='週間出来高'!K11 | C9: ='週間出来高'!K12 | D9: ='週間出来高'!K9 | E9: ='週間出来高'!K10
A10: 11月5週 | B10: ='週間出来高'!L11 | C10: ='週間出来高'!L12 | D10: ='週間出来高'!L9 | E10: ='週間出来高'!L10
A11: 12月1週 | B11: ='週間出来高'!M11 | C11: ='週間出来高'!M12 | D11: ='週間出来高'!M9 | E11: ='週間出来高'!M10
A12: 12月2週 | B12: ='週間出来高'!N11 | C12: ='週間出来高'!N12 | D12: ='週間出来高'!N9 | E12: ='週間出来高'!N10
A13: 12月3週 | B13: ='週間出来高'!O11 | C13: ='週間出来高'!O12 | D13: ='週間出来高'!O9 | E13: ='週間出来高'!O10
A14: 12月4週 | B14: ='週間出来高'!P11 | C14: ='週間出来高'!P12 | D14: ='週間出来高'!P9 | E14: ='週間出来高'!P10
A15: 1月1週 | B15: ='週間出来高'!Q11 | C15: ='週間出来高'!Q12 | D15: ='週間出来高'!Q9 | E15: ='週間出来高'!Q10
A16: 1月2週 | B16: ='週間出来高'!R11 | C16: ='週間出来高'!R12 | D16: ='週間出来高'!R9 | E16: ='週間出来高'!R10
A17: 1月3週 | B17: ='週間出来高'!S11 | C17: ='週間出来高'!S12 | D17: ='週間出来高'!S9 | E17: ='週間出来高'!S10
A18: 1月4週 | B18: ='週間出来高'!T11 | C18: ='週間出来高'!T12 | D18: ='週間出来高'!T9 | E18: ='週間出来高'!T10
A19: 2月1週 | B19: ='週間出来高'!U11 | C19: ='週間出来高'!U12 | D19: ='週間出来高'!U9 | E19: ='週間出来高'!U10
A20: 2月2週 | B20: ='週間出来高'!V11 | C20: ='週間出来高'!V12 | D20: ='週間出来高'!V9 | E20: ='週間出来高'!V10
A21: 2月3週 | B21: ='週間出来高'!W11 | C21: ='週間出来高'!W12 | D21: ='週間出来高'!W9 | E21: ='週間出来高'!W10
A22: 2月4週 | B22: ='週間出来高'!X11 | C22: ='週間出来高'!X12 | D22: ='週間出来高'!X9 | E22: ='週間出来高'!X10
A23: 3月1週 | B23: ='週間出来高'!Y11 | C23: ='週間出来高'!Y12 | D23: ='週間出来高'!Y9 | E23: ='週間出来高'!Y10
A24: 3月2週 | B24: ='週間出来高'!Z11 | C24: ='週間出来高'!Z12 | D24: ='週間出来高'!Z9 | E24: ='週間出来高'!Z10
A25: 3月3週 | B25: ='週間出来高'!AA11 | C25: ='週間出来高'!AA12 | D25: ='週間出来高'!AA9 | E25: ='週間出来高'!AA10
A26: 3月4週 | B26: ='週間出来高'!AB11 | C26: ='週間出来高'!AB12 | D26: ='週間出来高'!AB9 | E26: ='週間出来高'!AB10
A27: 3月5週 | B27: ='週間出来高'!AC11 | C27: ='週間出来高'!AC12 | D27: ='週間出来高'!AC9 | E27: ='週間出来高'!AC10
A30: 期間 | B30: 出来高金額（円） | C30: 累計出来高金額（円） | D30: 出来高率 | E30: 累計出来高率
A31: 着工前 | B31: 0 | C31: 0 | D31: 0 | E31: 0
A32: 11月 | B32: ='月別出来高'!E7 | C32: =B32 | D32: ='月別出来高'!E5 | E32: ='月別出来高'!E6
A33: 12月 | B33: ='月別出来高'!F7 | C33: =C32+B33 | D33: ='月別出来高'!F5 | E33: ='月別出来高'!F6
A34: 1月 | B34: ='月別出来高'!G7 | C34: =C33+B34 | D34: ='月別出来高'!G5 | E34: ='月別出来高'!G6
A35: 2月 | B35: ='月別出来高'!H7 | C35: =C34+B35 | D35: ='月別出来高'!H5 | E35: ='月別出来高'!H6
A36: 3月 | B36: ='月別出来高'!I7 | C36: =C35+B36 | D36: ='月別出来高'!I5 | E36: ='月別出来高'!I6
