Workbook

Sheet ①施工図リスト
A1: 現場／統括：、現場責任者：金子主任、主任：、担当： | AI1: 統責者 | AL1: 生産技術統括部 生産推進G
A2: 工事名： | C2: 椙山女学園 星が丘キャンパス大学会館食堂リニューアル工事 | AP2: 備考メモ | BH2: 完了 | BI2: {=BG3/BF3} -> 0.19444444
C3: 工期：2026/11/9～2027/03/31 | D3: PDS | H3: 生推G | K3: 監理者図面回覧 | AC3: 決定図 | AF3: 製作期間 | AG3: 施工予定 | AH3: 作図業者等 | AI3: 決定後変更図 | AM3: 図面終了確認日 | AN3: 備 考 | AQ3: 推進G受領日 業者から↑ | AR3: 現場へ提出日 生技が打２↑ | AS3: 現場へ提出日 生技が受領図↑ | AT3: 受領図２ | AV3: 受領図３ | BF3: {=COUNTA($AG$10:$AG$158)*6} -> 36 | BG3: {=COUNTA($G$10:$G$158)+COUNTA($J$10:$J$158)+COUNTA($L$10:$L$158)+COUNTA($M$10:$M$158)+COUNTA($S$10:$S$158)+COUNTA($T$10:$T$158)} -> 7 | BH3: 未完了 | BI3: {=1-BI2} -> 0.80555556
A4: 通し番号 | B4: 整 理 番 号 | C4: 敷地：m2 | D4: 外注予定日 | E4: 検図期間 | F4: 出図予定日 | G4: 受 図 日 | H4: 検図期間 | I4: 提出予定日 | J4: 提 出 日 | K4: 監理者確認期間 | L4: 打合 | N4: 打合2 | P4: 完了予定日 | Q4: 修正検図期間 | R4: 監理者確認期間 | S4: 受領1 | U4: 受領2 | W4: 受領3 | Y4: 受領4 | AA4: 受領5 | AC4: 予 定 日 | AD4: 決定限界日 | AE4: 決 定 日 | AI4: 1 | AK4: 2 | BH4: 赤色 | BI4: {=COUNTIFS($F$10:$F$113,"<="&TODAY(),$F$10:$F$113,">"&0,$G$10:$G$113,"="&"")+COUNTIFS($I$10:$I$113,"<="&TODAY(),$I$10:$I$113,">"&0,$J$10:$J$113,"="&"")+COUNTIFS($P$10:$P$113,"<="&TODAY(),$P$10:$P$113,">"&0,$L$10:$L$113,"="&"")+COUNTIFS($P$10:$P$113,"<="&TODAY(),$P$10:$P$113,">"&0,$M$10:$M$113,"="&"")+COUNTIFS($AC$10:$AC$113,"<="&TODAY(),$AC$10:$AC$113,">"&0,$S$10:$S$113,"="&"")+COUNTIFS($AC$10:$AC$113,"<="&TODAY(),$AC$10:$AC$113,">"&0,$T$10:$T$113,"="&"")} -> 1 | BJ4: {=BH4&": "&BI4&"個"} -> 赤色: 1個
C5: 建面：m2 | L5: 提 出 | M5: 返 却 | N5: 提 出 | O5: 返 却 | S5: 提 出 | T5: 返 却 | U5: 提 出 | V5: 返 却 | W5: 提 出 | X5: 返 却 | Y5: 提 出 | Z5: 返 却 | AA5: 提 出 | AB5: 返 却 | AI5: 提 出 | AJ5: 返 却 | AK5: 提 出 | AL5: 返 却 | AT5: 提出 | AU5: 返却 | AV5: 提出 | AW5: 返却 | BH5: 黄色 | BI5: {=COUNTIFS($F$10:$F$113,"<="&TODAY()+7,$F$10:$F$113,">"&0,$G$10:$G$113,"="&"")+COUNTIFS($I$10:$I$113,"<="&TODAY()+7,$I$10:$I$113,">"&0,$J$10:$J$113,"="&"")+COUNTIFS($P$10:$P$113,"<="&TODAY()+7,$P$10:$P$113,">"&0,$L$10:$L$113,"="&"")+COUNTIFS($P$10:$P$113,"<="&TODAY()+7,$P$10:$P$113,">"&0,$M$10:$M$113,"="&"")+COUNTIFS($AC$10:$AC$113,"<="&TODAY()+7,$AC$10:$AC$113,">"&0,$S$10:$S$113,"="&"")+COUNTIFS($AC$10:$AC$113,"<="&TODAY()+7,$AC$10:$AC$113,">"&0,$T$10:$T$113,"="&"")-BI4} -> 1 | BJ5: {=BH5&": "&BI5&"個"} -> 黄色: 1個
C6: 改修面積：675m2
C7: 構造：RC造 | AG7: {=AH7-2018} -> 7 | AH7: 2025 | BM7: {=COUNTIFS($AC$10:$AC$113,"<"&TODAY()+7,$AC$10:$AC$113,">"&0,$S$10:$S$113,"="&"")} -> 0
C8: 設計者：日建設計 | AG8: {=AH8-2018} -> 8 | AH8: {=AH7+1} -> 2026
C9: 図 面 名 称 | AG9: {=AH9-2018} -> 9 | AH9: {=AH8+1} -> 2027
A11: 0 | C11: 【躯体図】 | D11: {=IF(F11="","",F11-E11)} | F11: {=IF(I11="","",I11-H11)} | I11: {=IF(P11="","",P11-K11)} | P11: {=IF(AD11="","",AD11-R11-Q11)} | AD11: {=IF(AG11="","",AG11-AF11)}
A12: {=A11+1} -> 1 | B12: 躯体-1 | C12: １階・２階床伏図(1/50) | D12: {=IF(F12="","",F12-E12)} -> 46293 | E12: 7 | F12: 46300 | G12: 46301 | H12: 7 | I12: {=IF(P12="","",P12-K12)} -> 46318 | J12: 46301 | K12: 7 | L12: 46302 | M12: 46314 | P12: {=IF(AG12="","",AC12-R12-Q12)} -> 46325 | Q12: 7 | R12: 14 | AC12: 46346 | AD12: {=IF(AG12="","",AG12-AF12)} -> 46379 | AF12: 14 | AG12: 46393 | AH12: 2D作図 | AN12: １階SSD-1部分、２階ルーバー取り合い
A13: {=A12+1} -> 2 | D13: {=IF(F13="","",F13-E13)} | F13: {=IF(I13="","",I13-H13)} | I13: {=IF(P13="","",P13-K13)} | P13: {=IF(AG13="","",AC13-R13-Q13)} | AD13: {=IF(AG13="","",AG13-AF13)} | BE13: 0.14285714 | BF13: 0.85714286
A14: {=A13+1} -> 3 | D14: {=IF(F14="","",F14-E14)} | F14: {=IF(I14="","",I14-H14)} | I14: {=IF(P14="","",P14-K14)} | P14: {=IF(AG14="","",AC14-R14-Q14)} | AD14: {=IF(AG14="","",AG14-AF14)}
A15: {=A14+1} -> 4 | C15: 【仕上図】 | D15: {=IF(F15="","",F15-E15)} | F15: {=IF(I15="","",I15-H15)} | I15: {=IF(P15="","",P15-K15)} | P15: {=IF(AG15="","",AC15-R15-Q15)} | AD15: {=IF(AG15="","",AG15-AF15)}
A16: {=A15+1} -> 5 | B16: 仕上-1 | C16: １階平面詳細図(1/50) | D16: {=IF(F16="","",F16-E16)} -> 46279 | E16: 7 | F16: {=IF(I16="","",I16-H16)} -> 46286 | G16: 46281 | H16: 7 | I16: {=IF(P16="","",P16-K16)} -> 46293 | J16: 46282 | K16: 7 | L16: 46293 | M16: 46308 | P16: {=IF(AG16="","",AC16-R16-Q16)} -> 46300 | Q16: 7 | R16: 14 | S16: 46318 | AC16: 46321 | AD16: {=IF(AG16="","",AG16-AF16)} -> 46321 | AF16: 14 | AG16: 46335 | AH16: ２D作図 | AN16: 11/9着工
A17: {=A16+1} -> 6 | B17: 仕上-2 | C17: １階天井伏図(1/50) | D17: {=IF(F17="","",F17-E17)} -> 46301 | E17: 7 | F17: 46308 | G17: 46307 | H17: 7 | I17: {=IF(P17="","",P17-K17)} -> 46315 | J17: 46318 | K17: 7 | L17: 46318 | P17: {=IF(AG17="","",AC17-R17-Q17)} -> 46322 | Q17: 7 | R17: 14 | AC17: 46343 | AD17: {=IF(AG17="","",AG17-AF17)} -> 46338 | AF17: 7 | AG17: 46345 | AH17: ２D作図 | AN17: 11/19天井用墨出し
A18: {=A17+1} -> 7 | B18: 仕上-3 | C18: 食堂展開図(1/50) | D18: {=IF(F18="","",F18-E18)} -> 46317 | E18: 7 | F18: 46324 | H18: 7 | I18: {=IF(P18="","",P18-K18)} -> 46328 | K18: 7 | P18: {=IF(AG18="","",AC18-R18-Q18)} -> 46335 | Q18: 7 | R18: 14 | AC18: 46356 | AD18: {=IF(AG18="","",AG18-AF18)} -> 46363 | AF18: 7 | AG18: 46370 | AH18: ２D作図 | AN18: 12/14アルミルーバー下地
A19: {=A18+1} -> 8 | B19: 仕上-4 | C19: 解体範囲図（床・壁・天井） | D19: {=IF(F19="","",F19-E19)} -> 46297 | E19: 7 | F19: 46304 | G19: 46304 | H19: 7 | I19: {=IF(P19="","",P19-K19)} -> 46307 | J19: 46305 | K19: 7 | L19: 46310 | M19: 46318 | P19: {=IF(AG19="","",AC19-R19-Q19)} -> 46314 | Q19: 7 | R19: 7 | AC19: 46328 | AD19: {=IF(AG19="","",AG19-AF19)} -> 46331 | AF19: 7 | AG19: 46338 | AH19: ２D作図 | AN19: 11/12解体着手
A20: {=A19+1} -> 9 | B20: 仕上-5 | C20: 食堂床タイル割付図(1/50) | D20: {=IF(F20="","",F20-E20)} -> 46311 | E20: 7 | F20: 46318 | H20: 7 | I20: {=IF(P20="","",P20-K20)} -> 46332 | J20: 46324 | K20: 7 | L20: 46324 | P20: {=IF(AG20="","",AC20-R20-Q20)} -> 46339 | Q20: 7 | R20: 14 | AC20: 46360 | AD20: {=IF(AG20="","",AG20-AF20)} -> 46359 | AF20: 60 | AG20: 46419 | AH20: ２D作図 | AN20: 既存タイル割実測必要
A21: {=A20+1} -> 10 | D21: {=IF(F21="","",F21-E21)} | F21: {=IF(I21="","",I21-H21)} | I21: {=IF(P21="","",P21-K21)} | P21: {=IF(AG21="","",AC21-R21-Q21)} | AD21: {=IF(AG21="","",AG21-AF21)}
A22: {=A21+1} -> 11 | D22: {=IF(F22="","",F22-E22)} | F22: {=IF(I22="","",I22-H22)} | I22: {=IF(P22="","",P22-K22)} | P22: {=IF(AG22="","",AC22-R22-Q22)} | AD22: {=IF(AG22="","",AG22-AF22)}
A23: {=A21+1} -> 11 | D23: {=IF(F23="","",F23-E23)} | F23: {=IF(I23="","",I23-H23)} | I23: {=IF(P23="","",P23-K23)} | P23: {=IF(AG23="","",AC23-R23-Q23)} | AD23: {=IF(AG23="","",AG23-AF23)}
A24: {=A23+1} -> 12 | D24: {=IF(F24="","",F24-E24)} | F24: {=IF(I24="","",I24-H24)} | I24: {=IF(P24="","",P24-K24)} | P24: {=IF(AG24="","",AC24-R24-Q24)} | AD24: {=IF(AG24="","",AG24-AF24)}
A25: {=A24+1} -> 13 | D25: {=IF(F25="","",F25-E25)} | F25: {=IF(I25="","",I25-H25)} | I25: {=IF(P25="","",P25-K25)} | P25: {=IF(AG25="","",AC25-R25-Q25)} | AD25: {=IF(AG25="","",AG25-AF25)}
A26: {=A25+1} -> 14 | D26: {=IF(F26="","",F26-E26)} | F26: {=IF(I26="","",I26-H26)} | I26: {=IF(P26="","",P26-K26)} | P26: {=IF(AG26="","",AC26-R26-Q26)} | AD26: {=IF(AG26="","",AG26-AF26)}
A27: {=A26+1} -> 15 | D27: {=IF(F27="","",F27-E27)} | F27: {=IF(I27="","",I27-H27)} | I27: {=IF(P27="","",P27-K27)} | P27: {=IF(AG27="","",AC27-R27-Q27)} | AD27: {=IF(AG27="","",AG27-AF27)}
A28: {=A27+1} -> 16 | D28: {=IF(F28="","",F28-E28)} | F28: {=IF(I28="","",I28-H28)} | I28: {=IF(P28="","",P28-K28)} | P28: {=IF(AG28="","",AC28-R28-Q28)} | AD28: {=IF(AG28="","",AG28-AF28)}
A29: {=A28+1} -> 17 | D29: {=IF(F29="","",F29-E29)} | F29: {=IF(I29="","",I29-H29)} | I29: {=IF(P29="","",P29-K29)} | P29: {=IF(AG29="","",AC29-R29-Q29)} | AD29: {=IF(AG29="","",AG29-AF29)}
A30: {=A29+1} -> 18 | D30: {=IF(F30="","",F30-E30)} | F30: {=IF(I30="","",I30-H30)} | I30: {=IF(P30="","",P30-K30)} | P30: {=IF(AG30="","",AC30-R30-Q30)} | AD30: {=IF(AG30="","",AG30-AF30)}
A31: {=A30+1} -> 19 | D31: {=IF(F31="","",F31-E31)} | F31: {=IF(I31="","",I31-H31)} | I31: {=IF(P31="","",P31-K31)} | P31: {=IF(AG31="","",AC31-R31-Q31)} | AD31: {=IF(AG31="","",AG31-AF31)}
A32: {=A31+1} -> 20 | D32: {=IF(F32="","",F32-E32)} | F32: {=IF(I32="","",I32-H32)} | I32: {=IF(P32="","",P32-K32)} | P32: {=IF(AG32="","",AC32-R32-Q32)} | AD32: {=IF(AG32="","",AG32-AF32)}
A33: {=A32+1} -> 21 | D33: {=IF(F33="","",F33-E33)} | F33: {=IF(I33="","",I33-H33)} | I33: {=IF(P33="","",P33-K33)} | P33: {=IF(AG33="","",AC33-R33-Q33)} | AD33: {=IF(AG33="","",AG33-AF33)}
A34: {=A33+1} -> 22 | D34: {=IF(F34="","",F34-E34)} | F34: {=IF(I34="","",I34-H34)} | I34: {=IF(P34="","",P34-K34)} | P34: {=IF(AG34="","",AC34-R34-Q34)} | AD34: {=IF(AG34="","",AG34-AF34)}
A35: {=A34+1} -> 23 | D35: {=IF(F35="","",F35-E35)} | F35: {=IF(I35="","",I35-H35)} | I35: {=IF(P35="","",P35-K35)} | P35: {=IF(AG35="","",AC35-R35-Q35)} | AD35: {=IF(AG35="","",AG35-AF35)}
... A113: {=A112+1} -> 101 | D113: {=IF(F113="","",F113-E113)} | F113: {=IF(I113="","",I113-H113)} | I113: {=IF(P113="","",P113-K113)} | P113: {=IF(AG113="","",AC113-R113-Q113)} | AD113: {=IF(AG113="","",AG113-AF113)}
A114: {=A113+1} -> 102 | D114: {=IF(F114="","",F114-E114)} | F114: {=IF(I114="","",I114-H114)} | I114: {=IF(P114="","",P114-K114)} | P114: {=IF(AD114="","",AD114-R114-Q114)} | AD114: {=IF(AG114="","",AG114-AF114)}
A115: {=A114+1} -> 103 | D115: {=IF(F115="","",F115-E115)} | F115: {=IF(I115="","",I115-H115)} | I115: {=IF(P115="","",P115-K115)} | P115: {=IF(AD115="","",AD115-R115-Q115)} | AD115: {=IF(AG115="","",AG115-AF115)}
A116: {=A115+1} -> 104 | D116: {=IF(F116="","",F116-E116)} | F116: {=IF(I116="","",I116-H116)} | I116: {=IF(P116="","",P116-K116)} | P116: {=IF(AD116="","",AD116-R116-Q116)} | AD116: {=IF(AG116="","",AG116-AF116)}
A117: {=A116+1} -> 105 | D117: {=IF(F117="","",F117-E117)} | F117: {=IF(I117="","",I117-H117)} | I117: {=IF(P117="","",P117-K117)} | P117: {=IF(AD117="","",AD117-R117-Q117)} | AD117: {=IF(AG117="","",AG117-AF117)}
A118: {=A117+1} -> 106 | D118: {=IF(F118="","",F118-E118)} | F118: {=IF(I118="","",I118-H118)} | I118: {=IF(P118="","",P118-K118)} | P118: {=IF(AD118="","",AD118-R118-Q118)} | AD118: {=IF(AG118="","",AG118-AF118)}
...

Sheet ②製作図リスト
A1: {=①施工図リスト!A1} -> 現場／統括：、現場責任者：金子主任、主任：、担当： | AI1: 統責者 | AL1: 生産技術統括部 生産推進G
A2: 工事名： | C2: {=①施工図リスト!C2} -> 椙山女学園 星が丘キャンパス大学会館食堂リニューアル工事 | AP2: 備考メモ | BJ2: 完了 | BK2: {=BI3/BH3} -> 0.25308642
C3: =①施工図リスト!C3 -> 工期：2026/11/9～2027/03/31 | D3: 作図 手配 | E3: 現場記入 | F3: 業者作成 | H3: 生推G | K3: 監理者図面回覧 | AC3: 決定図 | AF3: 製作期間 | AG3: 施工予定 | AH3: 作図業者等 | AI3: 決定後変更図 | AM3: 図面終了確認日 | AN3: 備 考 | AQ3: 推進G受領日 業者から↑ | AR3: 現場へ提出日 生技が打２↑ | AS3: 現場へ提出日 生技が受領図↑ | AT3: 受領図２ | AV3: 受領図３ | BH3: {=COUNTA($AG$10:$AG$210)*6} -> 162 | BI3: {=COUNTA($G$10:$G$210)+COUNTA($J$10:$J$210)+COUNTA($L$10:$L$210)+COUNTA($M$10:$M$210)+COUNTA($S$10:$S$210)+COUNTA($T$10:$T$210)} -> 41 | BJ3: 未完了 | BK3: {=1-BK2} -> 0.74691358
A4: 通し番号 | B4: 整 理 番 号 | C4: =①施工図リスト!C4 -> 敷地：m2 | D4: 手配実施日 | E4: 業者決定 予定日 | F4: 出図予定日 | G4: 受 図 日 | H4: 検図期間 | I4: 提出予定日 | J4: 提 出 日 | K4: 監理者確認期間 | L4: 打合 | N4: 打合2 | P4: 完了予定日 | Q4: 修正検図期間 | R4: 監理者確認期間 | S4: 受領１ | U4: 受領２ | W4: 受領３ | Y4: 受領４ | AA4: 受領５ | AC4: 予 定 日 | AD4: 決定限界日 | AE4: 決 定 日 | AI4: 1 | AK4: 2 | BJ4: 赤色 | BK4: {=COUNTIFS($F$10:$F$116,"<="&TODAY(),$F$10:$F$116,">"&0,$G$10:$G$116,"="&"")+COUNTIFS($I$10:$I$116,"<="&TODAY(),$I$10:$I$116,">"&0,$J$10:$J$116,"="&"")+COUNTIFS($P$10:$P$116,"<="&TODAY(),$P$10:$P$116,">"&0,$L$10:$L$116,"="&"")+COUNTIFS($P$10:$P$116,"<="&TODAY(),$P$10:$P$116,">"&0,$M$10:$M$116,"="&"")+COUNTIFS($AC$10:$AC$116,"<="&TODAY(),$AC$10:$AC$116,">"&0,$S$10:$S$116,"="&"")+COUNTIFS($AC$10:$AC$116,"<="&TODAY(),$AC$10:$AC$116,">"&0,$T$10:$T$116,"="&"")} -> 7 | BL4: {=BJ4&": "&BK4&"個"} -> 赤色: 7個
C5: =①施工図リスト!C5 -> 建面：m2 | L5: 提 出 | M5: 返 却 | N5: 提 出 | O5: 返 却 | S5: 提 出 | T5: 返 却 | U5: 提 出 | V5: 返 却 | W5: 提 出 | X5: 返 却 | Y5: 提 出 | Z5: 返 却 | AA5: 提 出 | AB5: 返 却 | AI5: 提 出 | AJ5: 返 却 | AK5: 提 出 | AL5: 返 却 | AT5: 提出 | AU5: 返却 | AV5: 提出 | AW5: 返却 | BJ5: 黄色 | BK5: {=COUNTIFS($F$10:$F$116,"<="&TODAY()+7,$F$10:$F$116,">"&0,$G$10:$G$116,"="&"")+COUNTIFS($I$10:$I$116,"<="&TODAY()+7,$I$10:$I$116,">"&0,$J$10:$J$116,"="&"")+COUNTIFS($P$10:$P$116,"<="&TODAY()+7,$P$10:$P$116,">"&0,$L$10:$L$116,"="&"")+COUNTIFS($P$10:$P$116,"<="&TODAY()+7,$P$10:$P$116,">"&0,$M$10:$M$116,"="&"")+COUNTIFS($AC$10:$AC$116,"<="&TODAY()+7,$AC$10:$AC$116,">"&0,$S$10:$S$116,"="&"")+COUNTIFS($AC$10:$AC$116,"<="&TODAY()+7,$AC$10:$AC$116,">"&0,$T$10:$T$116,"="&"")-BK4} -> 3 | BL5: {=BJ5&": "&BK5&"個"} -> 黄色: 3個
C6: =①施工図リスト!C6 -> 改修面積：675m2
C7: =①施工図リスト!C7 -> 構造：RC造 | AG7: {=AH7-2018} -> 7 | AH7: 2025
C8: =①施工図リスト!C8 -> 設計者：日建設計 | AG8: {=AH8-2018} -> 8 | AH8: {=AH7+1} -> 2026
C9: 図 面 名 称 | AG9: {=AH9-2018} -> 9 | AH9: {=AH8+1} -> 2027
A11: 0 | C11: 金属工事（三友建材） | F11: {=IF(AG11="","",I11-H11)} | I11: {=IF(AG11="","",P11-K11)} | P11: {=IF(AG11="","",AC11-R11-Q11)} | AC11: =IF(AG11="","",WORKDAY(AG11-AF11+1,-1,{46329,46349,46384,46385,46386,46387,46388,46391,46398,46429,46441,46468})) | AD11: {=IF(AG11="","",$AG11-$AF11)}
A12: =A11+1 -> 1 | B12: 三友-4 | C12: 西側 1階食堂床見切り | F12: =IF(AG12="","",I12-H12) -> 46357 | G12: 46301 | H12: 7 | I12: =IF(AG12="","",P12-K12) -> 46364 | J12: 46302 | K12: 7 | L12: 46302 | M12: 46314 | P12: =IF(AG12="","",AC12-R12-Q12) -> 46371 | Q12: 7 | R12: 14 | AC12: =IF(AG12="","",WORKDAY(AG12-AF12+1,-1,{46329,46349,46384,46385,46386,46387,46388,46391,46398,46429,46441,46468})) -> 46392 | AD12: =IF(AG12="","",$AG12-$AF12) -> 46392 | AF12: 14 | AG12: 46406
A13: =A12+1 -> 2 | B13: 三友-7 | C13: 西側 ボックス席腰壁下地鉄骨 | F13: =IF(AG13="","",I13-H13) -> 46370 | G13: 46310 | H13: 7 | I13: =IF(AG13="","",P13-K13) -> 46377 | J13: 46321 | K13: 7 | L13: 46324 | P13: =IF(AG13="","",AC13-R13-Q13) -> 46384 | Q13: 7 | R13: 14 | AC13: =IF(AG13="","",WORKDAY(AG13-AF13+1,-1,{46329,46349,46384,46385,46386,46387,46388,46391,46398,46429,46441,46468})) -> 46405 | AD13: =IF(AG13="","",$AG13-$AF13) -> 46405 | AF13: 14 | AG13: 46419 | AN13: 製作２週間
A14: =A13+1 -> 3 | B14: 三友-8 | C14: 東側 吹抜け部天井下地鉄骨 | F14: =IF(AG14="","",I14-H14) -> 46325 | H14: 7 | I14: =IF(AG14="","",P14-K14) -> 46332 | K14: 7 | P14: =IF(AG14="","",AC14-R14-Q14) -> 46339 | Q14: 7 | R14: 14 | AC14: =IF(AG14="","",WORKDAY(AG14-AF14+1,-1,{46329,46349,46384,46385,46386,46387,46388,46391,46398,46429,46441,46468})) -> 46360 | AD14: =IF(AG14="","",$AG14-$AF14) -> 46360 | AF14: 14 | AG14: 46374
A15: =A14+1 -> 4 | B15: 三友-9 | C15: 東側 吸音ルーバー壁下地鉄骨 | F15: =IF(AG15="","",I15-H15) -> 46325 | G15: 46301 | H15: 7 | I15: =IF(AG15="","",P15-K15) -> 46332 | J15: 46302 | K15: 7 | L15: 46302 | M15: 46309 | P15: =IF(AG15="","",AC15-R15-Q15) -> 46339 | Q15: 7 | R15: 14 | AC15: =IF(AG15="","",WORKDAY(AG15-AF15+1,-1,{46329,46349,46384,46385,46386,46387,46388,46391,46398,46429,46441,46468})) -> 46360 | AD15: =IF(AG15="","",$AG15-$AF15) -> 46360 | AF15: 14 | AG15: 46374 | AN15: 製作２週間
A16: =A15+1 -> 5 | B16: 三友-10 | C16: 東側 吸音ルーバー壁⑤通り部天端塞ぎ | F16: =IF(AG16="","",I16-H16) -> 46325 | H16: 7 | I16: =IF(AG16="","",P16-K16) -> 46332 | K16: 7 | P16: =IF(AG16="","",AC16-R16-Q16) -> 46339 | Q16: 7 | R16: 14 | AC16: =IF(AG16="","",WORKDAY(AG16-AF16+1,-1,{46329,46349,46384,46385,46386,46387,46388,46391,46398,46429,46441,46468})) -> 46360 | AD16: =IF(AG16="","",$AG16-$AF16) -> 46360 | AF16: 14 | AG16: 46374
A17: =A16+1 -> 6 | B17: 三友-11 | C17: 東側 腰壁下地鉄骨 | F17: =IF(AG17="","",I17-H17) -> 46336 | G17: 46304 | H17: 7 | I17: =IF(AG17="","",P17-K17) -> 46343 | J17: 46309 | K17: 7 | L17: 46310 | M17: 46318 | P17: =IF(AG17="","",AC17-R17-Q17) -> 46350 | Q17: 7 | R17: 14 | AC17: =IF(AG17="","",WORKDAY(AG17-AF17+1,-1,{46329,46349,46384,46385,46386,46387,46388,46391,46398,46429,46441,46468})) -> 46371 | AD17: =IF(AG17="","",$AG17-$AF17) -> 46371 | AF17: 21 | AG17: 46392 | AN17: 製作３週間
A18: =A17+1 -> 7 | B18: 三友-12 | C18: 東側・西側 窓際カウンター下地 | F18: =IF(AG18="","",I18-H18) -> 46346 | H18: 7 | I18: =IF(AG18="","",P18-K18) -> 46353 | K18: 7 | P18: =IF(AG18="","",AC18-R18-Q18) -> 46360 | Q18: 7 | R18: 14 | AC18: =IF(AG18="","",WORKDAY(AG18-AF18+1,-1,{46329,46349,46384,46385,46386,46387,46388,46391,46398,46429,46441,46468})) -> 46381 | AD18: =IF(AG18="","",$AG18-$AF18) -> 46391 | AF18: 14 | AG18: 46405
A19: =A18+1 -> 8 | B19: 三友-13 | C19: 東側 壁見切り | F19: =IF(AG19="","",I19-H19) -> 46343 | H19: 7 | I19: =IF(AG19="","",P19-K19) -> 46350 | K19: 7 | P19: =IF(AG19="","",AC19-R19-Q19) -> 46357 | Q19: 7 | R19: 14 | AC19: =IF(AG19="","",WORKDAY(AG19-AF19+1,-1,{46329,46349,46384,46385,46386,46387,46388,46391,46398,46429,46441,46468})) -> 46378 | AD19: =IF(AG19="","",$AG19-$AF19) -> 46378 | AF19: 14 | AG19: 46392
A20: =A19+1 -> 9 | B20: 三友-14 | C20: 東側 自動扉安全柵 | F20: =IF(AG20="","",I20-H20) -> 46367 | G20: 46310 | H20: 7 | I20: =IF(AG20="","",P20-K20) -> 46374 | J20: 46318 | K20: 7 | L20: 46318 | P20: =IF(AG20="","",AC20-R20-Q20) -> 46381 | Q20: 7 | R20: 14 | AC20: =IF(AG20="","",WORKDAY(AG20-AF20+1,-1,{46329,46349,46384,46385,46386,46387,46388,46391,46398,46429,46441,46468})) -> 46402 | AD20: =IF(AG20="","",$AG20-$AF20) -> 46402 | AF20: 14 | AG20: 46416
A21: =A20+1 -> 10 | B21: 三友-15 | C21: 西側 壁アルミルーバー（天井裏下地込み） | F21: =IF(AG21="","",I21-H21) -> 46275 | G21: 46301 | H21: 7 | I21: =IF(AG21="","",P21-K21) -> 46282 | J21: 46302 | K21: 7 | L21: 46302 | M21: 46314 | P21: =IF(AG21="","",AC21-R21-Q21) -> 46289 | Q21: 7 | R21: 14 | S21: 46318 | AC21: =IF(AG21="","",WORKDAY(AG21-AF21+1,-1,{46329,46349,46384,46385,46386,46387,46388,46391,46398,46429,46441,46468})) -> 46310 | AD21: =IF(AG21="","",$AG21-$AF21) -> 46310 | AF21: 60 | AG21: 46370 | AN21: 製作２か月、9/30初回作図
A22: =A21+1 -> 11 | B22: 三友-16 | C22: 西側 ステンレスカウンター | F22: =IF(AG22="","",I22-H22) -> 46328 | H22: 7 | I22: =IF(AG22="","",P22-K22) -> 46335 | K22: 7 | P22: =IF(AG22="","",AC22-R22-Q22) -> 46342 | Q22: 7 | R22: 14 | AC22: =IF(AG22="","",WORKDAY(AG22-AF22+1,-1,{46329,46349,46384,46385,46386,46387,46388,46391,46398,46429,46441,46468})) -> 46363 | AD22: =IF(AG22="","",$AG22-$AF22) -> 46363 | AF22: 14 | AG22: 46377 | AN22: 壁モルタルアート1/5施工前想定
A23: =A22+1 -> 12 | B23: 三友-18 | C23: チャンバーボックス | F23: =IF(AG23="","",I23-H23) -> 46346 | H23: 7 | I23: =IF(AG23="","",P23-K23) -> 46353 | K23: 7 | P23: =IF(AG23="","",AC23-R23-Q23) -> 46360 | Q23: 7 | R23: 14 | AC23: =IF(AG23="","",WORKDAY(AG23-AF23+1,-1,{46329,46349,46384,46385,46386,46387,46388,46391,46398,46429,46441,46468})) -> 46381 | AD23: =IF(AG23="","",$AG23-$AF23) -> 46388 | AF23: 14 | AG23: 46402
A24: =A23+1 -> 13 | B24: 三友-19 | C24: チャンバーボックス グレーチング蓋 | F24: =IF(AG24="","",I24-H24) -> 46367 | H24: 7 | I24: =IF(AG24="","",P24-K24) -> 46374 | K24: 7 | P24: =IF(AG24="","",AC24-R24-Q24) -> 46381 | Q24: 7 | R24: 14 | AC24: =IF(AG24="","",WORKDAY(AG24-AF24+1,-1,{46329,46349,46384,46385,46386,46387,46388,46391,46398,46429,46441,46468})) -> 46402 | AD24: =IF(AG24="","",$AG24-$AF24) -> 46402 | AF24: 14 | AG24: 46416
A25: =A24+1 -> 14 | B25: 三友-20 | C25: 東側 照明ボックススチールパネル | F25: =IF(AG25="","",I25-H25) -> 46323 | H25: 7 | I25: =IF(AG25="","",P25-K25) -> 46330 | K25: 7 | P25: =IF(AG25="","",AC25-R25-Q25) -> 46337 | Q25: 7 | R25: 14 | AC25: =IF(AG25="","",WORKDAY(AG25-AF25+1,-1,{46329,46349,46384,46385,46386,46387,46388,46391,46398,46429,46441,46468})) -> 46358 | AD25: =IF(AG25="","",$AG25-$AF25) -> 46358 | AF25: 14 | AG25: 46372 | AN25: 天井下地着手想定
A26: =A25+1 -> 15 | B26: 三友-21 | C26: 西側 照明ボックススチールパネル | F26: =IF(AG26="","",I26-H26) -> 46330 | H26: 7 | I26: =IF(AG26="","",P26-K26) -> 46337 | K26: 7 | P26: =IF(AG26="","",AC26-R26-Q26) -> 46344 | Q26: 7 | R26: 14 | AC26: =IF(AG26="","",WORKDAY(AG26-AF26+1,-1,{46329,46349,46384,46385,46386,46387,46388,46391,46398,46429,46441,46468})) -> 46365 | AD26: =IF(AG26="","",$AG26-$AF26) -> 46365 | AF26: 14 | AG26: 46379 | AN26: 天井下地着手想定
A27: =A26+1 -> 16 | B27: 三友-24 | C27: ハンガードア下地鉄骨（追加） | F27: =IF(AG27="","",I27-H27) -> 46328 | G27: 46322 | H27: 7 | I27: =IF(AG27="","",P27-K27) -> 46335 | J27: 46324 | K27: 7 | L27: 46324 | P27: =IF(AG27="","",AC27-R27-Q27) -> 46342 | Q27: 7 | R27: 14 | AC27: =IF(AG27="","",WORKDAY(AG27-AF27+1,-1,{46329,46349,46384,46385,46386,46387,46388,46391,46398,46429,46441,46468})) -> 46363 | AD27: =IF(AG27="","",$AG27-$AF27) -> 46363 | AF27: 14 | AG27: 46377
A28: {=A27+1} -> 17 | F28: {=IF(AG28="","",I28-H28)} | I28: {=IF(AG28="","",P28-K28)} | P28: {=IF(AG28="","",AC28-R28-Q28)} | AC28: =IF(AG28="","",WORKDAY(AG28-AF28+1,-1,{46329,46349,46384,46385,46386,46387,46388,46391,46398,46429,46441,46468})) | AD28: {=IF(AG28="","",$AG28-$AF28)}
A29: {=A28+1} -> 18 | C29: 金建工事（三和シャッター） | F29: {=IF(AG29="","",I29-H29)} | I29: {=IF(AG29="","",P29-K29)} | P29: {=IF(AG29="","",AC29-R29-Q29)} | AC29: =IF(AG29="","",WORKDAY(AG29-AF29+1,-1,{46329,46349,46384,46385,46386,46387,46388,46391,46398,46429,46441,46468})) | AD29: {=IF(AG29="","",$AG29-$AF29)}
A30: {=A29+1} -> 19 | B30: 三和-1 | C30: 木製パネル張ハンガードア | F30: {=IF(AG30="","",I30-H30)} -> 46297 | G30: 46301 | H30: 7 | I30: {=IF(AG30="","",P30-K30)} -> 46304 | J30: 46302 | K30: 7 | L30: 46302 | M30: 46314 | P30: {=IF(AG30="","",AC30-R30-Q30)} -> 46311 | Q30: 7 | R30: 14 | AC30: =IF(AG30="","",WORKDAY(AG30-AF30+1,-1,{46329,46349,46384,46385,46386,46387,46388,46391,46398,46429,46441,46468})) -> 46332 | AD30: {=IF(AG30="","",$AG30-$AF30)} -> 46332 | AF30: 60 | AG30: 46392 | AN30: ３か所（中央ホール側）、製作２か月
A31: {=A30+1} -> 20 | B31: 三和-2 | C31: スチール製ガラリ扉更新（既設そのまま） | F31: {=IF(AG31="","",I31-H31)} | I31: {=IF(AG31="","",P31-K31)} | P31: {=IF(AG31="","",AC31-R31-Q31)} | AC31: =IF(AG31="","",WORKDAY(AG31-AF31+1,-1,{46329,46349,46384,46385,46386,46387,46388,46391,46398,46429,46441,46468})) | AD31: {=IF(AG31="","",$AG31-$AF31)} | AN31: SG-1（西側）製作２か月
A32: {=A31+1} -> 21 | B32: 三和-3 | C32: アルミ自動ドア | F32: {=IF(AG32="","",I32-H32)} -> 46297 | G32: 46290 | H32: 7 | I32: {=IF(AG32="","",P32-K32)} -> 46304 | J32: 46290 | K32: 7 | L32: 46293 | M32: 46297 | N32: 46302 | O32: 46314 | P32: {=IF(AG32="","",AC32-R32-Q32)} -> 46311 | Q32: 7 | R32: 14 | S32: 46317 | AC32: =IF(AG32="","",WORKDAY(AG32-AF32+1,-1,{46329,46349,46384,46385,46386,46387,46388,46391,46398,46429,46441,46468})) -> 46332 | AD32: {=IF(AG32="","",$AG32-$AF32)} -> 46334 | AF32: 60 | AG32: 46394 | AN32: AD1（中央ホール側）製作２か月
A33: {=A32+1} -> 22 | B33: 三和-4 | C33: （オペレータ改修） | F33: {=IF(AG33="","",I33-H33)} | I33: {=IF(AG33="","",P33-K33)} | P33: {=IF(AG33="","",AC33-R33-Q33)} | AC33: =IF(AG33="","",WORKDAY(AG33-AF33+1,-1,{46329,46349,46384,46385,46386,46387,46388,46391,46398,46429,46441,46468})) | AD33: {=IF(AG33="","",$AG33-$AF33)} | AN33: 9月調査、10月～手配・修理・交換
A34: =A33+1 -> 23 | B34: 三和-5 | C34: SD点検口 | F34: =IF(AG34="","",I34-H34) -> 46310 | G34: 46316 | H34: 7 | I34: =IF(AG34="","",P34-K34) -> 46317 | J34: 46317 | K34: 7 | L34: 46318 | P34: =IF(AG34="","",AC34-R34-Q34) -> 46324 | Q34: 7 | R34: 14 | AC34: =IF(AG34="","",WORKDAY(AG34-AF34+1,-1,{46329,46349,46384,46385,46386,46387,46388,46391,46398,46429,46441,46468})) -> 46345 | AD34: =IF(AG34="","",$AG34-$AF34) -> 46345 | AF34: 60 | AG34: 46405
A35: {=A34+1} -> 24 | F35: {=IF(AG35="","",I35-H35)} | I35: {=IF(AG35="","",P35-K35)} | P35: {=IF(AG35="","",AC35-R35-Q35)} | AC35: =IF(AG35="","",WORKDAY(AG35-AF35+1,-1,{46329,46349,46384,46385,46386,46387,46388,46391,46398,46429,46441,46468})) | AD35: {=IF(AG35="","",$AG35-$AF35)}
A36: {=A35+1} -> 25 | C36: 金建工事（三和タジマ） | F36: {=IF(AG36="","",I36-H36)} | I36: {=IF(AG36="","",P36-K36)} | P36: {=IF(AG36="","",AC36-R36-Q36)} | AC36: =IF(AG36="","",WORKDAY(AG36-AF36+1,-1,{46329,46349,46384,46385,46386,46387,46388,46391,46398,46429,46441,46468})) | AD36: {=IF(AG36="","",$AG36-$AF36)}
A37: {=A36+1} -> 26 | B37: タジマ-1 | C37: ステンレス製建具 | F37: {=IF(AG37="","",I37-H37)} -> 46286 | G37: 46282 | H37: 7 | I37: {=IF(AG37="","",P37-K37)} -> 46293 | J37: 46289 | K37: 7 | L37: 46293 | M37: 46297 | N37: 46302 | O37: 46309 | P37: {=IF(AG37="","",AC37-R37-Q37)} -> 46300 | Q37: 7 | R37: 7 | S37: 46318 | AC37: =IF(AG37="","",WORKDAY(AG37-AF37+1,-1,{46329,46349,46384,46385,46386,46387,46388,46391,46398,46429,46441,46468})) -> 46314 | AD37: {=IF(AG37="","",$AG37-$AF37)} -> 46314 | AF37: 80 | AG37: 46394 | AN37: SSD1（東デッキ側）製作２か月+塗装20日
A38: {=A37+1} -> 27 | F38: {=IF(AG38="","",I38-H38)} | I38: {=IF(AG38="","",P38-K38)} | P38: {=IF(AG38="","",AC38-R38-Q38)} | AC38: =IF(AG38="","",WORKDAY(AG38-AF38+1,-1,{46329,46349,46384,46385,46386,46387,46388,46391,46398,46429,46441,46468})) | AD38: {=IF(AG38="","",$AG38-$AF38)}
A39: {=A38+1} -> 28 | C39: 家具工事（ミディック） | F39: {=IF(AG39="","",I39-H39)} | I39: {=IF(AG39="","",P39-K39)} | P39: {=IF(AG39="","",AC39-R39-Q39)} | AC39: =IF(AG39="","",WORKDAY(AG39-AF39+1,-1,{46329,46349,46384,46385,46386,46387,46388,46391,46398,46429,46441,46468})) | AD39: {=IF(AG39="","",$AG39-$AF39)}
A40: {=A39+1} -> 29 | B40: MIDIC-1 | C40: 天井・壁_吸音ルーバー（ヒガノ） | F40: {=IF(AG40="","",I40-H40)} -> 46280 | G40: 46300 | H40: 7 | I40: {=IF(AG40="","",P40-K40)} -> 46287 | J40: 46302 | K40: 7 | L40: 46302 | M40: 46309 | P40: {=IF(AG40="","",AC40-R40-Q40)} -> 46294 | Q40: 7 | R40: 14 | AC40: =IF(AG40="","",WORKDAY(AG40-AF40+1,-1,{46329,46349,46384,46385,46386,46387,46388,46391,46398,46429,46441,46468})) -> 46315 | AD40: {=IF(AG40="","",$AG40-$AF40)} -> 46315 | AF40: 90 | AG40: 46405 | AN40: 製作３か月、9/18～作図
A41: {=A40+1} -> 30 | B41: MIDIC-2 | C41: ハンガードアパネル | F41: {=IF(AG41="","",I41-H41)} -> 46325 | H41: 7 | I41: {=IF(AG41="","",P41-K41)} -> 46332 | K41: 7 | P41: {=IF(AG41="","",AC41-R41-Q41)} -> 46339 | Q41: 7 | R41: 14 | AC41: =IF(AG41="","",WORKDAY(AG41-AF41+1,-1,{46329,46349,46384,46385,46386,46387,46388,46391,46398,46429,46441,46468})) -> 46360 | AD41: {=IF(AG41="","",$AG41-$AF41)} -> 46362 | AF41: 30 | AG41: 46392 | AN41: 製作１か月、HD搬入日想定
...

Sheet ③計画書要領書リスト
A1: =①施工図リスト!A1 -> 現場／統括：、現場責任者：金子主任、主任：、担当： | F1: {=①施工図リスト!AG7} -> 7 | G1: {=①施工図リスト!AH7} -> 2025 | J1: 統責者 | O1: 生産技術統括部 生産推進G
A2: 工事名： | C2: =①施工図リスト!C2 -> 椙山女学園 星が丘キャンパス大学会館食堂リニューアル工事 | F2: {=①施工図リスト!AG8} -> 8 | G2: {=①施工図リスト!AH8} -> 2026 | AH2: 備考メモ
F3: {=①施工図リスト!AG9} -> 9 | G3: {=①施工図リスト!AH9} -> 2027 | AQ3: 完了 | AR3: {=AP4/AO4} -> 0
A4: 通し 番号 | B4: 整理番号 | C4: 図 面 名 称 | D4: 協力業者 | E4: 推進G受領受領日 | F4: 推進G受領予定日 | G4: 推進G確認期間 | H4: 現場提出予定日 | I4: 現場提出日 | J4: 監理者確認期間 | K4: 監理者チェック版 提出日 | O4: 修正期間 | P4: 監理者確認期間 | Q4: 受領図 提出日 | S4: 受領図 提出日 | U4: 受領図 提出日 | W4: 受領図 提出日 | Y4: 受領図 提出日 | AA4: 監理者承認予定日 | AB4: 監理者承認日 | AC4: 製作期間 | AD4: 現場施工予定日 | AE4: 備考 | AH4: 推進G受領日 業者から↑ | AI4: 現場へ提出日 生技が打２↑ | AJ4: 現場へ提出日 生技が受領図↑ | AK4: 受領図２ 提出日 | AM4: 受領図３ 提出日 | AO4: {=COUNTA($AD$7:$AD$146)*5} -> 75 | AP4: {=COUNTA($I$7:$I$146)+COUNTA($K$7:$K$146)+COUNTA($L$7:$L$146)+COUNTA($Q$7:$Q$146)+COUNTA($R$7:$R$146)} -> 0 | AQ4: 未完了 | AR4: {=1-AR3} -> 1
K5: 1回目 | M5: 2回目 | Q5: 提出 | R5: 返却 | S5: 提出 | T5: 返却 | U5: 提出 | V5: 返却 | W5: 提出 | X5: 返却 | Y5: 提出 | Z5: 返却 | AK5: 提出 | AL5: 返却 | AM5: 提出 | AN5: 返却
K6: 提出 | L6: 返却 | M6: 提出 | N6: 返却
A7: 0 | F7: {=IF(AD7="","",H7-G7)} | H7: {=IF(AD7="","",AA7-J7-P7-O7)} | AA7: {=IF(AD7="","",AD7-AC7)}
A8: {=A7+1} -> 1 | B8: 計-1 | C8: 総合施工計画書 | D8: 現場 | F8: {=IF($AD8="","",$H8-$G8)} -> 46293 | G8: 7 | H8: {=IF($AD8="","",$AA8-$J8-$P8-$O8)} -> 46300 | I8: 46324 | J8: 7 | K8: 46324 | O8: 7 | P8: 14 | AA8: {=IF(AD8="","",AD8-AC8)} -> 46328 | AC8: 7 | AD8: 46335 | AE8: 仮設・搬入計画等
A9: {=A8+1} -> 2 | B9: 計-2 | C9: コンクリート配合計画書 | D9: TCトレーディング | F9: {=IF($AD9="","",$H9-$G9)} -> 46370 | H9: {=IF($AD9="","",$AA9-$J9-$P9-$O9)} -> 46370 | AA9: {=IF(AD9="","",AD9-AC9)} -> 46370 | AD9: 46370 | AE9: 小口工事、不要
A10: {=A9+1} -> 3 | B10: 計-3 | C10: コンクリート工事施工計画書 | D10: アン・シティ | F10: {=IF($AD10="","",$H10-$G10)} -> 46370 | H10: {=IF($AD10="","",$AA10-$J10-$P10-$O10)} -> 46370 | AA10: {=IF(AD10="","",AD10-AC10)} -> 46370 | AD10: 46370 | AE10: 小口工事、不要
A11: {=A10+1} -> 4 | B11: 計-4 | C11: あと施工アンカー工事施工計画書 | D11: アン・シティ | F11: {=IF($AD11="","",$H11-$G11)} -> 46345 | G11: 7 | H11: {=IF($AD11="","",$AA11-$J11-$P11-$O11)} -> 46352 | J11: 7 | O11: 7 | P11: 14 | AA11: {=IF(AD11="","",AD11-AC11)} -> 46380 | AC11: 14 | AD11: 46394 | AE11: 0918質疑対応とする⇒設計図に記載有り。とりあえず作成する
A12: {=A11+1} -> 5 | B12: 計-5 | C12: シーリング工事施工計画書 | D12: アジケン | E12: 46298 | F12: {=IF($AD12="","",$H12-$G12)} -> 46351 | G12: 7 | H12: {=IF($AD12="","",$AA12-$J12-$P12-$O12)} -> 46358 | J12: 7 | O12: 7 | P12: 14 | AA12: {=IF(AD12="","",AD12-AC12)} -> 46386 | AC12: 14 | AD12: 46400
A13: {=A12+1} -> 6 | B13: 計-6 | C13: タイル工事施工計画書 | D13: 協和建材 | F13: {=IF($AD13="","",$H13-$G13)} -> 46370 | G13: 7 | H13: {=IF($AD13="","",$AA13-$J13-$P13-$O13)} -> 46377 | J13: 7 | O13: 7 | P13: 14 | AA13: {=IF(AD13="","",AD13-AC13)} -> 46405 | AC13: 14 | AD13: 46419 | AE13: 西：2/1～/東：2/12～
A14: {=A13+1} -> 7 | B14: 計-7 | C14: 金属工事施工計画書 | D14: 三友建材 | F14: {=IF($AD14="","",$H14-$G14)} -> 46321 | G14: 7 | H14: {=IF($AD14="","",$AA14-$J14-$P14-$O14)} -> 46328 | J14: 7 | O14: 7 | P14: 14 | AA14: {=IF(AD14="","",AD14-AC14)} -> 46356 | AC14: 14 | AD14: 46370
A15: {=A14+1} -> 8 | B15: 計-8 | C15: 鋼製建具工事（AD・SG） | D15: 三和シャッター | F15: {=IF($AD15="","",$H15-$G15)} -> 46345 | G15: 7 | H15: {=IF($AD15="","",$AA15-$J15-$P15-$O15)} -> 46352 | J15: 7 | O15: 7 | P15: 14 | AA15: {=IF(AD15="","",AD15-AC15)} -> 46380 | AC15: 14 | AD15: 46394 | AE15: SG中止
A16: {=A15+1} -> 9 | B16: 計-9 | C16: 鋼製建具工事（SSD） | D16: 三和タジマ | E16: 46294 | F16: {=IF($AD16="","",$H16-$G16)} -> 46330 | G16: 7 | H16: {=IF($AD16="","",$AA16-$J16-$P16-$O16)} -> 46337 | J16: 7 | O16: 7 | P16: 14 | AA16: {=IF(AD16="","",AD16-AC16)} -> 46365 | AC16: 14 | AD16: 46379
A17: {=A16+1} -> 10 | B17: 計-10 | C17: 造作家具工事施工計画書 | D17: ミディック | F17: {=IF($AD17="","",$H17-$G17)} -> 46356 | G17: 7 | H17: {=IF($AD17="","",$AA17-$J17-$P17-$O17)} -> 46363 | J17: 7 | O17: 7 | P17: 14 | AA17: {=IF(AD17="","",AD17-AC17)} -> 46391 | AC17: 14 | AD17: 46405
A18: {=A17+1} -> 11 | B18: 計-11 | C18: ガラス工事施工計画書 | D18: 竹甚板硝子 | F18: {=IF($AD18="","",$H18-$G18)} -> 46366 | H18: {=IF($AD18="","",$AA18-$J18-$P18-$O18)} -> 46366 | AA18: {=IF(AD18="","",AD18-AC18)} -> 46366 | AD18: 46366 | AE18: 小口工事、不要
A19: {=A18+1} -> 12 | B19: 計-12 | C19: 左官工事施工計画書 | D19: 浪花組 | F19: {=IF($AD19="","",$H19-$G19)} -> 46359 | G19: 7 | H19: {=IF($AD19="","",$AA19-$J19-$P19-$O19)} -> 46366 | J19: 7 | O19: 7 | P19: 14 | AA19: {=IF(AD19="","",AD19-AC19)} -> 46394 | AC19: 14 | AD19: 46408
A20: {=A19+1} -> 13 | B20: 計-13 | C20: 塗装工事施工計画書 | D20: 中部岩佐 | E20: 46295 | F20: {=IF($AD20="","",$H20-$G20)} -> 46329 | G20: 7 | H20: {=IF($AD20="","",$AA20-$J20-$P20-$O20)} -> 46336 | J20: 7 | O20: 7 | P20: 14 | AA20: {=IF(AD20="","",AD20-AC20)} -> 46364 | AC20: 14 | AD20: 46378
A21: {=A20+1} -> 14 | B21: 計-14 | C21: 内装工事（LGS･ボード工事）施工計画書 | D21: ミルックス | F21: {=IF($AD21="","",$H21-$G21)} -> 46323 | G21: 7 | H21: {=IF($AD21="","",$AA21-$J21-$P21-$O21)} -> 46330 | J21: 7 | O21: 7 | P21: 14 | AA21: {=IF(AD21="","",AD21-AC21)} -> 46358 | AC21: 14 | AD21: 46372
A22: {=A21+1} -> 15 | B22: 計-15 | C22: 鋼製床工事施工計画書 | D22: 中部フローリング | F22: {=IF($AD22="","",$H22-$G22)} -> 46366 | G22: 7 | H22: {=IF($AD22="","",$AA22-$J22-$P22-$O22)} -> 46373 | J22: 7 | O22: 7 | P22: 7 | AA22: {=IF(AD22="","",AD22-AC22)} -> 46394 | AC22: 14 | AD22: 46408
A23: {=A22+1} -> 16 | F23: {=IF($AD23="","",$H23-$G23)} | H23: {=IF($AD23="","",$AA23-$J23-$P23-$O23)} | AA23: {=IF(AD23="","",AD23-AC23)}
A24: {=A23+1} -> 17 | C24: 【 報告書 】 | F24: {=IF($AD24="","",$H24-$G24)} | H24: {=IF($AD24="","",$AA24-$J24-$P24-$O24)} | AA24: {=IF(AD24="","",AD24-AC24)}
A25: {=A24+1} -> 18 | B25: 報-1 | C25: 石綿含有建材事前調査結果報告書 | F25: {=IF($AD25="","",$H25-$G25)} | H25: {=IF($AD25="","",$AA25-$J25-$P25-$O25)} | AA25: {=IF(AD25="","",AD25-AC25)} | AE25: 10/16調査実施
A26: {=A25+1} -> 19 | B26: 報-2 | C26: 化学物質の濃度測定 | F26: {=IF($AD26="","",$H26-$G26)} | H26: {=IF($AD26="","",$AA26-$J26-$P26-$O26)} | AA26: {=IF(AD26="","",AD26-AC26)} | AE26: 引渡し前
A27: {=A26+1} -> 20 | F27: {=IF($AD27="","",$H27-$G27)} | H27: {=IF($AD27="","",$AA27-$J27-$P27-$O27)} | AA27: {=IF(AD27="","",AD27-AC27)}
A28: {=A27+1} -> 21 | F28: {=IF($AD28="","",$H28-$G28)} | H28: {=IF($AD28="","",$AA28-$J28-$P28-$O28)} | AA28: {=IF(AD28="","",AD28-AC28)}
A29: {=A28+1} -> 22 | F29: {=IF($AD29="","",$H29-$G29)} | H29: {=IF($AD29="","",$AA29-$J29-$P29-$O29)} | AA29: {=IF(AD29="","",AD29-AC29)}
A30: {=A29+1} -> 23 | F30: {=IF($AD30="","",$H30-$G30)} | H30: {=IF($AD30="","",$AA30-$J30-$P30-$O30)} | AA30: {=IF(AD30="","",AD30-AC30)}
A31: {=A30+1} -> 24 | F31: {=IF($AD31="","",$H31-$G31)} | H31: {=IF($AD31="","",$AA31-$J31-$P31-$O31)} | AA31: {=IF(AD31="","",AD31-AC31)}
A32: {=A31+1} -> 25 | F32: {=IF($AD32="","",$H32-$G32)} | H32: {=IF($AD32="","",$AA32-$J32-$P32-$O32)} | AA32: {=IF(AD32="","",AD32-AC32)}
A33: {=A32+1} -> 26 | F33: {=IF($AD33="","",$H33-$G33)} | H33: {=IF($AD33="","",$AA33-$J33-$P33-$O33)} | AA33: {=IF(AD33="","",AD33-AC33)}
A34: {=A33+1} -> 27 | F34: {=IF($AD34="","",$H34-$G34)} | H34: {=IF($AD34="","",$AA34-$J34-$P34-$O34)} | AA34: {=IF(AD34="","",AD34-AC34)}
A35: {=A34+1} -> 28 | F35: {=IF($AD35="","",$H35-$G35)} | H35: {=IF($AD35="","",$AA35-$J35-$P35-$O35)} | AA35: {=IF(AD35="","",AD35-AC35)}
A36: {=A35+1} -> 29 | F36: {=IF($AD36="","",$H36-$G36)} | H36: {=IF($AD36="","",$AA36-$J36-$P36-$O36)} | AA36: {=IF(AD36="","",AD36-AC36)}
A37: {=A36+1} -> 30 | C37: 【 仕 上 】 | F37: {=IF($AD37="","",$H37-$G37)} | H37: {=IF($AD37="","",$AA37-$J37-$P37-$O37)} | AA37: {=IF(AD37="","",AD37-AC37)}
A38: {=A37+1} -> 31 | C38: 屋根工事施工計画書 | F38: {=IF($AD38="","",$H38-$G38)} | H38: {=IF($AD38="","",$AA38-$J38-$P38-$O38)} | AA38: {=IF(AD38="","",AD38-AC38)}
A39: {=A38+1} -> 32 | C39: 外壁工事施工計画書 | F39: {=IF($AD39="","",$H39-$G39)} | H39: {=IF($AD39="","",$AA39-$J39-$P39-$O39)} | AA39: {=IF(AD39="","",AD39-AC39)}
A40: {=A39+1} -> 33 | C40: 防水工事施工計画書 | F40: {=IF($AD40="","",$H40-$G40)} | H40: {=IF($AD40="","",$AA40-$J40-$P40-$O40)} | AA40: {=IF(AD40="","",AD40-AC40)}
...
